Workbook

Sheet Summary
F1: EP Details (Grouped) | L1: Major Errors (Grouped) | T1: Minor Errors (Grouped) | AI1: Unclassified (Grouped)
A2: S. No. | B2: SHOW NAMES | C2: Show IDs | D2: DE title | E2: QC'd months (dump) | F2: Ep Count | G2: First EP with error | H2: Last EP with error | I2: Additional EPs | J2: Total Errors | K2: Total Errors Per Episode | L2: Major Errors | M2: Abrupt cut / Jerk | N2: Audio quality | O2: Gramatically incorrect (voa) | P2: Incorrect name | Q2: Mispronunciation | R2: Missed line / Word | S2: Script error | T2: Minor Errors | U2: Acting | V2: Audio Regenerated | W2: Background noise | X2: Breathing noise | Y2: Clarity of speech | Z2: Distorted sound | AA2: Fumble / Mumble | AB2: Modulation | AC2: Physical noise of VOA | AD2: Repetition | AE2: Sibilance | AF2: Tone change | AG2: Unusual gap / pause | AH2: Voice processing & editing | AI2: Unclassified | AJ2: BGM/SFX | AK2: Pending | AL2: Resolved | AM2: Ignore | AN2: Unique Ep with error | AO2: Unique Error Rate | AP2: Unique Ep with Major error | AQ2: Unique Error Major Rate | AR2: Unique Ep with Minor error | AS2: Unique Error Minor Rate
A3: 1 | B3: The Miracle Heiress | C3: 9a175f97e92a638a5697307799ea3b8b8f419aac | D3: Die Wundererbin | E3: Aug, Sept | F3: =IFERROR(VLOOKUP($C3,'Show IDs'!$A:$D,4,FALSE)+0,"") -> 304 | G3: =IFERROR(_xlfn.MINIFS('QC Dump (clean)'!$F:$F,'QC Dump (clean)'!$A:$A,$C3,'QC Dump (clean)'!$M:$M,"<>Not an error"),"") -> 1 | H3: =IFERROR(_xlfn.MAXIFS('QC Dump (clean)'!$F:$F,'QC Dump (clean)'!$A:$A,$C3,'QC Dump (clean)'!$M:$M,"<>Not an error"),"") -> 300 | J3: =L3+T3+AI3 -> 1340 | K3: =IFERROR(J3/$F3,"") -> 4.4078947 | L3: =COUNTIFS('QC Dump (clean)'!$A:$A,$C3,'QC Dump (clean)'!$M:$M,"Major") -> 1301 | M3: =COUNTIFS('QC Dump (clean)'!$A:$A,$C3,'QC Dump (clean)'!$L:$L,M$2,'QC Dump (clean)'!$M:$M,"Major") -> 3 | N3: =COUNTIFS('QC Dump (clean)'!$A:$A,$C3,'QC Dump (clean)'!$L:$L,N$2,'QC Dump (clean)'!$M:$M,"Major") -> 37 | O3: =COUNTIFS('QC Dump (clean)'!$A:$A,$C3,'QC Dump (clean)'!$L:$L,O$2,'QC Dump (clean)'!$M:$M,"Major") -> 0 | P3: =COUNTIFS('QC Dump (clean)'!$A:$A,$C3,'QC Dump (clean)'!$L:$L,P$2,'QC Dump (clean)'!$M:$M,"Major") -> 1 | Q3: =COUNTIFS('QC Dump (clean)'!$A:$A,$C3,'QC Dump (clean)'!$L:$L,Q$2,'QC Dump (clean)'!$M:$M,"Major") -> 152 | R3: =COUNTIFS('QC Dump (clean)'!$A:$A,$C3,'QC Dump (clean)'!$L:$L,R$2,'QC Dump (clean)'!$M:$M,"Major") -> 1 | S3: =COUNTIFS('QC Dump (clean)'!$A:$A,$C3,'QC Dump (clean)'!$L:$L,S$2,'QC Dump (clean)'!$M:$M,"Major") -> 1107 | T3: =COUNTIFS('QC Dump (clean)'!$A:$A,$C3,'QC Dump (clean)'!$M:$M,"Minor") -> 39 | U3: =COUNTIFS('QC Dump (clean)'!$A:$A,$C3,'QC Dump (clean)'!$L:$L,U$2,'QC Dump (clean)'!$M:$M,"Minor") -> 1 | V3: =COUNTIFS('QC Dump (clean)'!$A:$A,$C3,'QC Dump (clean)'!$L:$L,V$2,'QC Dump (clean)'!$M:$M,"Minor") -> 0 | W3: =COUNTIFS('QC Dump (clean)'!$A:$A,$C3,'QC Dump (clean)'!$L:$L,W$2,'QC Dump (clean)'!$M:$M,"Minor") -> 0 | X3: =COUNTIFS('QC Dump (clean)'!$A:$A,$C3,'QC Dump (clean)'!$L:$L,X$2,'QC Dump (clean)'!$M:$M,"Minor") -> 0 | Y3: =COUNTIFS('QC Dump (clean)'!$A:$A,$C3,'QC Dump (clean)'!$L:$L,Y$2,'QC Dump (clean)'!$M:$M,"Minor") -> 0 | Z3: =COUNTIFS('QC Dump (clean)'!$A:$A,$C3,'QC Dump (clean)'!$L:$L,Z$2,'QC Dump (clean)'!$M:$M,"Minor") -> 0 | AA3: =COUNTIFS('QC Dump (clean)'!$A:$A,$C3,'QC Dump (clean)'!$L:$L,AA$2,'QC Dump (clean)'!$M:$M,"Minor") -> 0 | AB3: =COUNTIFS('QC Dump (clean)'!$A:$A,$C3,'QC Dump (clean)'!$L:$L,AB$2,'QC Dump (clean)'!$M:$M,"Minor") -> 33 | ... AH3: =COUNTIFS('QC Dump (clean)'!$A:$A,$C3,'QC Dump (clean)'!$L:$L,AH$2,'QC Dump (clean)'!$M:$M,"Minor") -> 0 | AI3: =COUNTIFS('QC Dump (clean)'!$A:$A,$C3,'QC Dump (clean)'!$M:$M,"Unclassified") -> 0 | AJ3: =COUNTIFS('QC Dump (clean)'!$A:$A,$C3,'QC Dump (clean)'!$L:$L,AJ$2,'QC Dump (clean)'!$M:$M,"Unclassified") -> 0 | AK3: =COUNTIFS('QC Dump (clean)'!$A:$A,$C3,'QC Dump (clean)'!$H:$H,"Pending",'QC Dump (clean)'!$M:$M,"<>Not an error") -> 87 | AL3: =COUNTIFS('QC Dump (clean)'!$A:$A,$C3,'QC Dump (clean)'!$H:$H,"Resolved",'QC Dump (clean)'!$M:$M,"<>Not an error") -> 1116 | AM3: =COUNTIFS('QC Dump (clean)'!$A:$A,$C3,'QC Dump (clean)'!$H:$H,"Ignore",'QC Dump (clean)'!$M:$M,"<>Not an error") -> 137 | AN3: =SUMIFS('QC Dump (clean)'!$S:$S,'QC Dump (clean)'!$A:$A,$C3) -> 285 | AO3: =IFERROR(AN3/$F3,"") -> 0.9375 | AP3: =SUMIFS('QC Dump (clean)'!$T:$T,'QC Dump (clean)'!$A:$A,$C3) -> 280 | AQ3: =IFERROR(AP3/$F3,"") -> 0.92105263 | AR3: =SUMIFS('QC Dump (clean)'!$U:$U,'QC Dump (clean)'!$A:$A,$C3) -> 35 | AS3: =IFERROR(AR3/$F3,"") -> 0.11513158
A4: 2 | B4: Primal Partners | C4: 819eabfbd96880cd7f6d42202600e24bdb384108 | D4: Primal Partners (New) | E4: Sept | F4: =IFERROR(VLOOKUP($C4,'Show IDs'!$A:$D,4,FALSE)+0,"") -> 176 | G4: =IFERROR(_xlfn.MINIFS('QC Dump (clean)'!$F:$F,'QC Dump (clean)'!$A:$A,$C4,'QC Dump (clean)'!$M:$M,"<>Not an error"),"") -> 1 | H4: =IFERROR(_xlfn.MAXIFS('QC Dump (clean)'!$F:$F,'QC Dump (clean)'!$A:$A,$C4,'QC Dump (clean)'!$M:$M,"<>Not an error"),"") -> 151 | J4: =L4+T4+AI4 -> 839 | K4: =IFERROR(J4/$F4,"") -> 4.7670455 | L4: =COUNTIFS('QC Dump (clean)'!$A:$A,$C4,'QC Dump (clean)'!$M:$M,"Major") -> 825 | M4: =COUNTIFS('QC Dump (clean)'!$A:$A,$C4,'QC Dump (clean)'!$L:$L,M$2,'QC Dump (clean)'!$M:$M,"Major") -> 2 | N4: =COUNTIFS('QC Dump (clean)'!$A:$A,$C4,'QC Dump (clean)'!$L:$L,N$2,'QC Dump (clean)'!$M:$M,"Major") -> 11 | O4: =COUNTIFS('QC Dump (clean)'!$A:$A,$C4,'QC Dump (clean)'!$L:$L,O$2,'QC Dump (clean)'!$M:$M,"Major") -> 0 | P4: =COUNTIFS('QC Dump (clean)'!$A:$A,$C4,'QC Dump (clean)'!$L:$L,P$2,'QC Dump (clean)'!$M:$M,"Major") -> 0 | Q4: =COUNTIFS('QC Dump (clean)'!$A:$A,$C4,'QC Dump (clean)'!$L:$L,Q$2,'QC Dump (clean)'!$M:$M,"Major") -> 39 | R4: =COUNTIFS('QC Dump (clean)'!$A:$A,$C4,'QC Dump (clean)'!$L:$L,R$2,'QC Dump (clean)'!$M:$M,"Major") -> 0 | S4: =COUNTIFS('QC Dump (clean)'!$A:$A,$C4,'QC Dump (clean)'!$L:$L,S$2,'QC Dump (clean)'!$M:$M,"Major") -> 773 | T4: =COUNTIFS('QC Dump (clean)'!$A:$A,$C4,'QC Dump (clean)'!$M:$M,"Minor") -> 14 | U4: =COUNTIFS('QC Dump (clean)'!$A:$A,$C4,'QC Dump (clean)'!$L:$L,U$2,'QC Dump (clean)'!$M:$M,"Minor") -> 0 | V4: =COUNTIFS('QC Dump (clean)'!$A:$A,$C4,'QC Dump (clean)'!$L:$L,V$2,'QC Dump (clean)'!$M:$M,"Minor") -> 0 | W4: =COUNTIFS('QC Dump (clean)'!$A:$A,$C4,'QC Dump (clean)'!$L:$L,W$2,'QC Dump (clean)'!$M:$M,"Minor") -> 0 | X4: =COUNTIFS('QC Dump (clean)'!$A:$A,$C4,'QC Dump (clean)'!$L:$L,X$2,'QC Dump (clean)'!$M:$M,"Minor") -> 0 | Y4: =COUNTIFS('QC Dump (clean)'!$A:$A,$C4,'QC Dump (clean)'!$L:$L,Y$2,'QC Dump (clean)'!$M:$M,"Minor") -> 0 | Z4: =COUNTIFS('QC Dump (clean)'!$A:$A,$C4,'QC Dump (clean)'!$L:$L,Z$2,'QC Dump (clean)'!$M:$M,"Minor") -> 0 | AA4: =COUNTIFS('QC Dump (clean)'!$A:$A,$C4,'QC Dump (clean)'!$L:$L,AA$2,'QC Dump (clean)'!$M:$M,"Minor") -> 0 | AB4: =COUNTIFS('QC Dump (clean)'!$A:$A,$C4,'QC Dump (clean)'!$L:$L,AB$2,'QC Dump (clean)'!$M:$M,"Minor") -> 12 | ... AH4: =COUNTIFS('QC Dump (clean)'!$A:$A,$C4,'QC Dump (clean)'!$L:$L,AH$2,'QC Dump (clean)'!$M:$M,"Minor") -> 0 | AI4: =COUNTIFS('QC Dump (clean)'!$A:$A,$C4,'QC Dump (clean)'!$M:$M,"Unclassified") -> 0 | AJ4: =COUNTIFS('QC Dump (clean)'!$A:$A,$C4,'QC Dump (clean)'!$L:$L,AJ$2,'QC Dump (clean)'!$M:$M,"Unclassified") -> 0 | AK4: =COUNTIFS('QC Dump (clean)'!$A:$A,$C4,'QC Dump (clean)'!$H:$H,"Pending",'QC Dump (clean)'!$M:$M,"<>Not an error") -> 417 | AL4: =COUNTIFS('QC Dump (clean)'!$A:$A,$C4,'QC Dump (clean)'!$H:$H,"Resolved",'QC Dump (clean)'!$M:$M,"<>Not an error") -> 418 | AM4: =COUNTIFS('QC Dump (clean)'!$A:$A,$C4,'QC Dump (clean)'!$H:$H,"Ignore",'QC Dump (clean)'!$M:$M,"<>Not an error") -> 4 | AN4: =SUMIFS('QC Dump (clean)'!$S:$S,'QC Dump (clean)'!$A:$A,$C4) -> 129 | AO4: =IFERROR(AN4/$F4,"") -> 0.73295455 | AP4: =SUMIFS('QC Dump (clean)'!$T:$T,'QC Dump (clean)'!$A:$A,$C4) -> 129 | AQ4: =IFERROR(AP4/$F4,"") -> 0.73295455 | AR4: =SUMIFS('QC Dump (clean)'!$U:$U,'QC Dump (clean)'!$A:$A,$C4) -> 11 | AS4: =IFERROR(AR4/$F4,"") -> 0.0625
A5: 3 | B5: Zompirewolf | C5: 294cd7d130be8bb0326127c52ff2769fcf9a956d | D5: Zompirewolf: Die Geburt Einer Legende | E5: Aug, Sept | F5: =IFERROR(VLOOKUP($C5,'Show IDs'!$A:$D,4,FALSE)+0,"") -> 571 | G5: =IFERROR(_xlfn.MINIFS('QC Dump (clean)'!$F:$F,'QC Dump (clean)'!$A:$A,$C5,'QC Dump (clean)'!$M:$M,"<>Not an error"),"") -> 316 | H5: =IFERROR(_xlfn.MAXIFS('QC Dump (clean)'!$F:$F,'QC Dump (clean)'!$A:$A,$C5,'QC Dump (clean)'!$M:$M,"<>Not an error"),"") -> 569 | J5: =L5+T5+AI5 -> 666 | K5: =IFERROR(J5/$F5,"") -> 1.1663748 | L5: =COUNTIFS('QC Dump (clean)'!$A:$A,$C5,'QC Dump (clean)'!$M:$M,"Major") -> 660 | M5: =COUNTIFS('QC Dump (clean)'!$A:$A,$C5,'QC Dump (clean)'!$L:$L,M$2,'QC Dump (clean)'!$M:$M,"Major") -> 7 | N5: =COUNTIFS('QC Dump (clean)'!$A:$A,$C5,'QC Dump (clean)'!$L:$L,N$2,'QC Dump (clean)'!$M:$M,"Major") -> 0 | O5: =COUNTIFS('QC Dump (clean)'!$A:$A,$C5,'QC Dump (clean)'!$L:$L,O$2,'QC Dump (clean)'!$M:$M,"Major") -> 0 | P5: =COUNTIFS('QC Dump (clean)'!$A:$A,$C5,'QC Dump (clean)'!$L:$L,P$2,'QC Dump (clean)'!$M:$M,"Major") -> 0 | Q5: =COUNTIFS('QC Dump (clean)'!$A:$A,$C5,'QC Dump (clean)'!$L:$L,Q$2,'QC Dump (clean)'!$M:$M,"Major") -> 246 | R5: =COUNTIFS('QC Dump (clean)'!$A:$A,$C5,'QC Dump (clean)'!$L:$L,R$2,'QC Dump (clean)'!$M:$M,"Major") -> 0 | S5: =COUNTIFS('QC Dump (clean)'!$A:$A,$C5,'QC Dump (clean)'!$L:$L,S$2,'QC Dump (clean)'!$M:$M,"Major") -> 407 | T5: =COUNTIFS('QC Dump (clean)'!$A:$A,$C5,'QC Dump (clean)'!$M:$M,"Minor") -> 6 | U5: =COUNTIFS('QC Dump (clean)'!$A:$A,$C5,'QC Dump (clean)'!$L:$L,U$2,'QC Dump (clean)'!$M:$M,"Minor") -> 0 | V5: =COUNTIFS('QC Dump (clean)'!$A:$A,$C5,'QC Dump (clean)'!$L:$L,V$2,'QC Dump (clean)'!$M:$M,"Minor") -> 0 | W5: =COUNTIFS('QC Dump (clean)'!$A:$A,$C5,'QC Dump (clean)'!$L:$L,W$2,'QC Dump (clean)'!$M:$M,"Minor") -> 0 | X5: =COUNTIFS('QC Dump (clean)'!$A:$A,$C5,'QC Dump (clean)'!$L:$L,X$2,'QC Dump (clean)'!$M:$M,"Minor") -> 3 | Y5: =COUNTIFS('QC Dump (clean)'!$A:$A,$C5,'QC Dump (clean)'!$L:$L,Y$2,'QC Dump (clean)'!$M:$M,"Minor") -> 0 | Z5: =COUNTIFS('QC Dump (clean)'!$A:$A,$C5,'QC Dump (clean)'!$L:$L,Z$2,'QC Dump (clean)'!$M:$M,"Minor") -> 0 | AA5: =COUNTIFS('QC Dump (clean)'!$A:$A,$C5,'QC Dump (clean)'!$L:$L,AA$2,'QC Dump (clean)'!$M:$M,"Minor") -> 0 | AB5: =COUNTIFS('QC Dump (clean)'!$A:$A,$C5,'QC Dump (clean)'!$L:$L,AB$2,'QC Dump (clean)'!$M:$M,"Minor") -> 3 | ... AH5: =COUNTIFS('QC Dump (clean)'!$A:$A,$C5,'QC Dump (clean)'!$L:$L,AH$2,'QC Dump (clean)'!$M:$M,"Minor") -> 0 | AI5: =COUNTIFS('QC Dump (clean)'!$A:$A,$C5,'QC Dump (clean)'!$M:$M,"Unclassified") -> 0 | AJ5: =COUNTIFS('QC Dump (clean)'!$A:$A,$C5,'QC Dump (clean)'!$L:$L,AJ$2,'QC Dump (clean)'!$M:$M,"Unclassified") -> 0 | AK5: =COUNTIFS('QC Dump (clean)'!$A:$A,$C5,'QC Dump (clean)'!$H:$H,"Pending",'QC Dump (clean)'!$M:$M,"<>Not an error") -> 26 | AL5: =COUNTIFS('QC Dump (clean)'!$A:$A,$C5,'QC Dump (clean)'!$H:$H,"Resolved",'QC Dump (clean)'!$M:$M,"<>Not an error") -> 578 | AM5: =COUNTIFS('QC Dump (clean)'!$A:$A,$C5,'QC Dump (clean)'!$H:$H,"Ignore",'QC Dump (clean)'!$M:$M,"<>Not an error") -> 62 | AN5: =SUMIFS('QC Dump (clean)'!$S:$S,'QC Dump (clean)'!$A:$A,$C5) -> 164 | AO5: =IFERROR(AN5/$F5,"") -> 0.28721541 | AP5: =SUMIFS('QC Dump (clean)'!$T:$T,'QC Dump (clean)'!$A:$A,$C5) -> 164 | AQ5: =IFERROR(AP5/$F5,"") -> 0.28721541 | AR5: =SUMIFS('QC Dump (clean)'!$U:$U,'QC Dump (clean)'!$A:$A,$C5) -> 6 | AS5: =IFERROR(AR5/$F5,"") -> 0.010507881
A6: 4 | B6: The Silent Rebirth | C6: f855eae3dfc9aadc286f38e8d5e70cc6a599f238 | D6: Wiedergeboren Für Rache | E6: Sept | F6: =IFERROR(VLOOKUP($C6,'Show IDs'!$A:$D,4,FALSE)+0,"") -> 50 | G6: =IFERROR(_xlfn.MINIFS('QC Dump (clean)'!$F:$F,'QC Dump (clean)'!$A:$A,$C6,'QC Dump (clean)'!$M:$M,"<>Not an error"),"") -> 1 | H6: =IFERROR(_xlfn.MAXIFS('QC Dump (clean)'!$F:$F,'QC Dump (clean)'!$A:$A,$C6,'QC Dump (clean)'!$M:$M,"<>Not an error"),"") -> 50 | J6: =L6+T6+AI6 -> 390 | K6: =IFERROR(J6/$F6,"") -> 7.8 | L6: =COUNTIFS('QC Dump (clean)'!$A:$A,$C6,'QC Dump (clean)'!$M:$M,"Major") -> 362 | M6: =COUNTIFS('QC Dump (clean)'!$A:$A,$C6,'QC Dump (clean)'!$L:$L,M$2,'QC Dump (clean)'!$M:$M,"Major") -> 0 | N6: =COUNTIFS('QC Dump (clean)'!$A:$A,$C6,'QC Dump (clean)'!$L:$L,N$2,'QC Dump (clean)'!$M:$M,"Major") -> 0 | O6: =COUNTIFS('QC Dump (clean)'!$A:$A,$C6,'QC Dump (clean)'!$L:$L,O$2,'QC Dump (clean)'!$M:$M,"Major") -> 0 | P6: =COUNTIFS('QC Dump (clean)'!$A:$A,$C6,'QC Dump (clean)'!$L:$L,P$2,'QC Dump (clean)'!$M:$M,"Major") -> 0 | Q6: =COUNTIFS('QC Dump (clean)'!$A:$A,$C6,'QC Dump (clean)'!$L:$L,Q$2,'QC Dump (clean)'!$M:$M,"Major") -> 3 | R6: =COUNTIFS('QC Dump (clean)'!$A:$A,$C6,'QC Dump (clean)'!$L:$L,R$2,'QC Dump (clean)'!$M:$M,"Major") -> 0 | S6: =COUNTIFS('QC Dump (clean)'!$A:$A,$C6,'QC Dump (clean)'!$L:$L,S$2,'QC Dump (clean)'!$M:$M,"Major") -> 359 | T6: =COUNTIFS('QC Dump (clean)'!$A:$A,$C6,'QC Dump (clean)'!$M:$M,"Minor") -> 28 | U6: =COUNTIFS('QC Dump (clean)'!$A:$A,$C6,'QC Dump (clean)'!$L:$L,U$2,'QC Dump (clean)'!$M:$M,"Minor") -> 0 | V6: =COUNTIFS('QC Dump (clean)'!$A:$A,$C6,'QC Dump (clean)'!$L:$L,V$2,'QC Dump (clean)'!$M:$M,"Minor") -> 3 | W6: =COUNTIFS('QC Dump (clean)'!$A:$A,$C6,'QC Dump (clean)'!$L:$L,W$2,'QC Dump (clean)'!$M:$M,"Minor") -> 0 | X6: =COUNTIFS('QC Dump (clean)'!$A:$A,$C6,'QC Dump (clean)'!$L:$L,X$2,'QC Dump (clean)'!$M:$M,"Minor") -> 0 | Y6: =COUNTIFS('QC Dump (clean)'!$A:$A,$C6,'QC Dump (clean)'!$L:$L,Y$2,'QC Dump (clean)'!$M:$M,"Minor") -> 0 | Z6: =COUNTIFS('QC Dump (clean)'!$A:$A,$C6,'QC Dump (clean)'!$L:$L,Z$2,'QC Dump (clean)'!$M:$M,"Minor") -> 23 | AA6: =COUNTIFS('QC Dump (clean)'!$A:$A,$C6,'QC Dump (clean)'!$L:$L,AA$2,'QC Dump (clean)'!$M:$M,"Minor") -> 0 | AB6: =COUNTIFS('QC Dump (clean)'!$A:$A,$C6,'QC Dump (clean)'!$L:$L,AB$2,'QC Dump (clean)'!$M:$M,"Minor") -> 2 | ... AH6: =COUNTIFS('QC Dump (clean)'!$A:$A,$C6,'QC Dump (clean)'!$L:$L,AH$2,'QC Dump (clean)'!$M:$M,"Minor") -> 0 | AI6: =COUNTIFS('QC Dump (clean)'!$A:$A,$C6,'QC Dump (clean)'!$M:$M,"Unclassified") -> 0 | AJ6: =COUNTIFS('QC Dump (clean)'!$A:$A,$C6,'QC Dump (clean)'!$L:$L,AJ$2,'QC Dump (clean)'!$M:$M,"Unclassified") -> 0 | AK6: =COUNTIFS('QC Dump (clean)'!$A:$A,$C6,'QC Dump (clean)'!$H:$H,"Pending",'QC Dump (clean)'!$M:$M,"<>Not an error") -> 3 | AL6: =COUNTIFS('QC Dump (clean)'!$A:$A,$C6,'QC Dump (clean)'!$H:$H,"Resolved",'QC Dump (clean)'!$M:$M,"<>Not an error") -> 341 | AM6: =COUNTIFS('QC Dump (clean)'!$A:$A,$C6,'QC Dump (clean)'!$H:$H,"Ignore",'QC Dump (clean)'!$M:$M,"<>Not an error") -> 46 | AN6: =SUMIFS('QC Dump (clean)'!$S:$S,'QC Dump (clean)'!$A:$A,$C6) -> 50 | AO6: =IFERROR(AN6/$F6,"") -> 1 | AP6: =SUMIFS('QC Dump (clean)'!$T:$T,'QC Dump (clean)'!$A:$A,$C6) -> 50 | AQ6: =IFERROR(AP6/$F6,"") -> 1 | AR6: =SUMIFS('QC Dump (clean)'!$U:$U,'QC Dump (clean)'!$A:$A,$C6) -> 22 | AS6: =IFERROR(AR6/$F6,"") -> 0.44
A7: 5 | B7: The Secret Life of an Accidental Heiress | C7: 806152088c4f0f13e40c0788e7bc440106d13b1a | D7: The Secret Life of an Accidental Heiress | E7: Sept | F7: =IFERROR(VLOOKUP($C7,'Show IDs'!$A:$D,4,FALSE)+0,"") -> 42 | G7: =IFERROR(_xlfn.MINIFS('QC Dump (clean)'!$F:$F,'QC Dump (clean)'!$A:$A,$C7,'QC Dump (clean)'!$M:$M,"<>Not an error"),"") -> 1 | H7: =IFERROR(_xlfn.MAXIFS('QC Dump (clean)'!$F:$F,'QC Dump (clean)'!$A:$A,$C7,'QC Dump (clean)'!$M:$M,"<>Not an error"),"") -> 42 | J7: =L7+T7+AI7 -> 376 | K7: =IFERROR(J7/$F7,"") -> 8.952381 | L7: =COUNTIFS('QC Dump (clean)'!$A:$A,$C7,'QC Dump (clean)'!$M:$M,"Major") -> 350 | M7: =COUNTIFS('QC Dump (clean)'!$A:$A,$C7,'QC Dump (clean)'!$L:$L,M$2,'QC Dump (clean)'!$M:$M,"Major") -> 0 | N7: =COUNTIFS('QC Dump (clean)'!$A:$A,$C7,'QC Dump (clean)'!$L:$L,N$2,'QC Dump (clean)'!$M:$M,"Major") -> 0 | O7: =COUNTIFS('QC Dump (clean)'!$A:$A,$C7,'QC Dump (clean)'!$L:$L,O$2,'QC Dump (clean)'!$M:$M,"Major") -> 0 | P7: =COUNTIFS('QC Dump (clean)'!$A:$A,$C7,'QC Dump (clean)'!$L:$L,P$2,'QC Dump (clean)'!$M:$M,"Major") -> 0 | Q7: =COUNTIFS('QC Dump (clean)'!$A:$A,$C7,'QC Dump (clean)'!$L:$L,Q$2,'QC Dump (clean)'!$M:$M,"Major") -> 157 | R7: =COUNTIFS('QC Dump (clean)'!$A:$A,$C7,'QC Dump (clean)'!$L:$L,R$2,'QC Dump (clean)'!$M:$M,"Major") -> 0 | S7: =COUNTIFS('QC Dump (clean)'!$A:$A,$C7,'QC Dump (clean)'!$L:$L,S$2,'QC Dump (clean)'!$M:$M,"Major") -> 193 | T7: =COUNTIFS('QC Dump (clean)'!$A:$A,$C7,'QC Dump (clean)'!$M:$M,"Minor") -> 26 | U7: =COUNTIFS('QC Dump (clean)'!$A:$A,$C7,'QC Dump (clean)'!$L:$L,U$2,'QC Dump (clean)'!$M:$M,"Minor") -> 0 | V7: =COUNTIFS('QC Dump (clean)'!$A:$A,$C7,'QC Dump (clean)'!$L:$L,V$2,'QC Dump (clean)'!$M:$M,"Minor") -> 0 | W7: =COUNTIFS('QC Dump (clean)'!$A:$A,$C7,'QC Dump (clean)'!$L:$L,W$2,'QC Dump (clean)'!$M:$M,"Minor") -> 0 | X7: =COUNTIFS('QC Dump (clean)'!$A:$A,$C7,'QC Dump (clean)'!$L:$L,X$2,'QC Dump (clean)'!$M:$M,"Minor") -> 0 | Y7: =COUNTIFS('QC Dump (clean)'!$A:$A,$C7,'QC Dump (clean)'!$L:$L,Y$2,'QC Dump (clean)'!$M:$M,"Minor") -> 0 | Z7: =COUNTIFS('QC Dump (clean)'!$A:$A,$C7,'QC Dump (clean)'!$L:$L,Z$2,'QC Dump (clean)'!$M:$M,"Minor") -> 0 | AA7: =COUNTIFS('QC Dump (clean)'!$A:$A,$C7,'QC Dump (clean)'!$L:$L,AA$2,'QC Dump (clean)'!$M:$M,"Minor") -> 0 | AB7: =COUNTIFS('QC Dump (clean)'!$A:$A,$C7,'QC Dump (clean)'!$L:$L,AB$2,'QC Dump (clean)'!$M:$M,"Minor") -> 2 | ... AH7: =COUNTIFS('QC Dump (clean)'!$A:$A,$C7,'QC Dump (clean)'!$L:$L,AH$2,'QC Dump (clean)'!$M:$M,"Minor") -> 24 | AI7: =COUNTIFS('QC Dump (clean)'!$A:$A,$C7,'QC Dump (clean)'!$M:$M,"Unclassified") -> 0 | AJ7: =COUNTIFS('QC Dump (clean)'!$A:$A,$C7,'QC Dump (clean)'!$L:$L,AJ$2,'QC Dump (clean)'!$M:$M,"Unclassified") -> 0 | AK7: =COUNTIFS('QC Dump (clean)'!$A:$A,$C7,'QC Dump (clean)'!$H:$H,"Pending",'QC Dump (clean)'!$M:$M,"<>Not an error") -> 376 | AL7: =COUNTIFS('QC Dump (clean)'!$A:$A,$C7,'QC Dump (clean)'!$H:$H,"Resolved",'QC Dump (clean)'!$M:$M,"<>Not an error") -> 0 | AM7: =COUNTIFS('QC Dump (clean)'!$A:$A,$C7,'QC Dump (clean)'!$H:$H,"Ignore",'QC Dump (clean)'!$M:$M,"<>Not an error") -> 0 | AN7: =SUMIFS('QC Dump (clean)'!$S:$S,'QC Dump (clean)'!$A:$A,$C7) -> 41 | AO7: =IFERROR(AN7/$F7,"") -> 0.97619048 | AP7: =SUMIFS('QC Dump (clean)'!$T:$T,'QC Dump (clean)'!$A:$A,$C7) -> 41 | AQ7: =IFERROR(AP7/$F7,"") -> 0.97619048 | AR7: =SUMIFS('QC Dump (clean)'!$U:$U,'QC Dump (clean)'!$A:$A,$C7) -> 18 | AS7: =IFERROR(AR7/$F7,"") -> 0.42857143
A8: 6 | B8: Thorns and Thrones | C8: 60392f2f8a29ae2294a4d279a3033aeaa01affa7 | D8: Fluch Und Krone | E8: Aug, Sept | F8: =IFERROR(VLOOKUP($C8,'Show IDs'!$A:$D,4,FALSE)+0,"") -> 81 | G8: =IFERROR(_xlfn.MINIFS('QC Dump (clean)'!$F:$F,'QC Dump (clean)'!$A:$A,$C8,'QC Dump (clean)'!$M:$M,"<>Not an error"),"") -> 3 | H8: =IFERROR(_xlfn.MAXIFS('QC Dump (clean)'!$F:$F,'QC Dump (clean)'!$A:$A,$C8,'QC Dump (clean)'!$M:$M,"<>Not an error"),"") -> 81 | J8: =L8+T8+AI8 -> 240 | K8: =IFERROR(J8/$F8,"") -> 2.962963 | L8: =COUNTIFS('QC Dump (clean)'!$A:$A,$C8,'QC Dump (clean)'!$M:$M,"Major") -> 235 | M8: =COUNTIFS('QC Dump (clean)'!$A:$A,$C8,'QC Dump (clean)'!$L:$L,M$2,'QC Dump (clean)'!$M:$M,"Major") -> 0 | N8: =COUNTIFS('QC Dump (clean)'!$A:$A,$C8,'QC Dump (clean)'!$L:$L,N$2,'QC Dump (clean)'!$M:$M,"Major") -> 0 | O8: =COUNTIFS('QC Dump (clean)'!$A:$A,$C8,'QC Dump (clean)'!$L:$L,O$2,'QC Dump (clean)'!$M:$M,"Major") -> 0 | P8: =COUNTIFS('QC Dump (clean)'!$A:$A,$C8,'QC Dump (clean)'!$L:$L,P$2,'QC Dump (clean)'!$M:$M,"Major") -> 0 | Q8: =COUNTIFS('QC Dump (clean)'!$A:$A,$C8,'QC Dump (clean)'!$L:$L,Q$2,'QC Dump (clean)'!$M:$M,"Major") -> 169 | R8: =COUNTIFS('QC Dump (clean)'!$A:$A,$C8,'QC Dump (clean)'!$L:$L,R$2,'QC Dump (clean)'!$M:$M,"Major") -> 0 | S8: =COUNTIFS('QC Dump (clean)'!$A:$A,$C8,'QC Dump (clean)'!$L:$L,S$2,'QC Dump (clean)'!$M:$M,"Major") -> 66 | T8: =COUNTIFS('QC Dump (clean)'!$A:$A,$C8,'QC Dump (clean)'!$M:$M,"Minor") -> 5 | U8: =COUNTIFS('QC Dump (clean)'!$A:$A,$C8,'QC Dump (clean)'!$L:$L,U$2,'QC Dump (clean)'!$M:$M,"Minor") -> 4 | V8: =COUNTIFS('QC Dump (clean)'!$A:$A,$C8,'QC Dump (clean)'!$L:$L,V$2,'QC Dump (clean)'!$M:$M,"Minor") -> 0 | W8: =COUNTIFS('QC Dump (clean)'!$A:$A,$C8,'QC Dump (clean)'!$L:$L,W$2,'QC Dump (clean)'!$M:$M,"Minor") -> 0 | X8: =COUNTIFS('QC Dump (clean)'!$A:$A,$C8,'QC Dump (clean)'!$L:$L,X$2,'QC Dump (clean)'!$M:$M,"Minor") -> 0 | Y8: =COUNTIFS('QC Dump (clean)'!$A:$A,$C8,'QC Dump (clean)'!$L:$L,Y$2,'QC Dump (clean)'!$M:$M,"Minor") -> 1 | Z8: =COUNTIFS('QC Dump (clean)'!$A:$A,$C8,'QC Dump (clean)'!$L:$L,Z$2,'QC Dump (clean)'!$M:$M,"Minor") -> 0 | AA8: =COUNTIFS('QC Dump (clean)'!$A:$A,$C8,'QC Dump (clean)'!$L:$L,AA$2,'QC Dump (clean)'!$M:$M,"Minor") -> 0 | AB8: =COUNTIFS('QC Dump (clean)'!$A:$A,$C8,'QC Dump (clean)'!$L:$L,AB$2,'QC Dump (clean)'!$M:$M,"Minor") -> 0 | ... AH8: =COUNTIFS('QC Dump (clean)'!$A:$A,$C8,'QC Dump (clean)'!$L:$L,AH$2,'QC Dump (clean)'!$M:$M,"Minor") -> 0 | AI8: =COUNTIFS('QC Dump (clean)'!$A:$A,$C8,'QC Dump (clean)'!$M:$M,"Unclassified") -> 0 | AJ8: =COUNTIFS('QC Dump (clean)'!$A:$A,$C8,'QC Dump (clean)'!$L:$L,AJ$2,'QC Dump (clean)'!$M:$M,"Unclassified") -> 0 | AK8: =COUNTIFS('QC Dump (clean)'!$A:$A,$C8,'QC Dump (clean)'!$H:$H,"Pending",'QC Dump (clean)'!$M:$M,"<>Not an error") -> 240 | AL8: =COUNTIFS('QC Dump (clean)'!$A:$A,$C8,'QC Dump (clean)'!$H:$H,"Resolved",'QC Dump (clean)'!$M:$M,"<>Not an error") -> 0 | AM8: =COUNTIFS('QC Dump (clean)'!$A:$A,$C8,'QC Dump (clean)'!$H:$H,"Ignore",'QC Dump (clean)'!$M:$M,"<>Not an error") -> 0 | AN8: =SUMIFS('QC Dump (clean)'!$S:$S,'QC Dump (clean)'!$A:$A,$C8) -> 69 | AO8: =IFERROR(AN8/$F8,"") -> 0.85185185 | AP8: =SUMIFS('QC Dump (clean)'!$T:$T,'QC Dump (clean)'!$A:$A,$C8) -> 66 | AQ8: =IFERROR(AP8/$F8,"") -> 0.81481481 | AR8: =SUMIFS('QC Dump (clean)'!$U:$U,'QC Dump (clean)'!$A:$A,$C8) -> 5 | AS8: =IFERROR(AR8/$F8,"") -> 0.061728395
A9: 7 | B9: Bride of a dragon | C9: 4baec2ac0f23302985d2ad577e111504bd88c99c | D9: Die Braut Des Drachenkönigs | E9: Aug, Sept | F9: =IFERROR(VLOOKUP($C9,'Show IDs'!$A:$D,4,FALSE)+0,"") -> 71 | G9: =IFERROR(_xlfn.MINIFS('QC Dump (clean)'!$F:$F,'QC Dump (clean)'!$A:$A,$C9,'QC Dump (clean)'!$M:$M,"<>Not an error"),"") -> 1 | H9: =IFERROR(_xlfn.MAXIFS('QC Dump (clean)'!$F:$F,'QC Dump (clean)'!$A:$A,$C9,'QC Dump (clean)'!$M:$M,"<>Not an error"),"") -> 71 | J9: =L9+T9+AI9 -> 221 | K9: =IFERROR(J9/$F9,"") -> 3.1126761 | L9: =COUNTIFS('QC Dump (clean)'!$A:$A,$C9,'QC Dump (clean)'!$M:$M,"Major") -> 203 | M9: =COUNTIFS('QC Dump (clean)'!$A:$A,$C9,'QC Dump (clean)'!$L:$L,M$2,'QC Dump (clean)'!$M:$M,"Major") -> 0 | N9: =COUNTIFS('QC Dump (clean)'!$A:$A,$C9,'QC Dump (clean)'!$L:$L,N$2,'QC Dump (clean)'!$M:$M,"Major") -> 0 | O9: =COUNTIFS('QC Dump (clean)'!$A:$A,$C9,'QC Dump (clean)'!$L:$L,O$2,'QC Dump (clean)'!$M:$M,"Major") -> 0 | P9: =COUNTIFS('QC Dump (clean)'!$A:$A,$C9,'QC Dump (clean)'!$L:$L,P$2,'QC Dump (clean)'!$M:$M,"Major") -> 0 | Q9: =COUNTIFS('QC Dump (clean)'!$A:$A,$C9,'QC Dump (clean)'!$L:$L,Q$2,'QC Dump (clean)'!$M:$M,"Major") -> 180 | R9: =COUNTIFS('QC Dump (clean)'!$A:$A,$C9,'QC Dump (clean)'!$L:$L,R$2,'QC Dump (clean)'!$M:$M,"Major") -> 0 | S9: =COUNTIFS('QC Dump (clean)'!$A:$A,$C9,'QC Dump (clean)'!$L:$L,S$2,'QC Dump (clean)'!$M:$M,"Major") -> 23 | T9: =COUNTIFS('QC Dump (clean)'!$A:$A,$C9,'QC Dump (clean)'!$M:$M,"Minor") -> 18 | U9: =COUNTIFS('QC Dump (clean)'!$A:$A,$C9,'QC Dump (clean)'!$L:$L,U$2,'QC Dump (clean)'!$M:$M,"Minor") -> 15 | V9: =COUNTIFS('QC Dump (clean)'!$A:$A,$C9,'QC Dump (clean)'!$L:$L,V$2,'QC Dump (clean)'!$M:$M,"Minor") -> 0 | W9: =COUNTIFS('QC Dump (clean)'!$A:$A,$C9,'QC Dump (clean)'!$L:$L,W$2,'QC Dump (clean)'!$M:$M,"Minor") -> 0 | X9: =COUNTIFS('QC Dump (clean)'!$A:$A,$C9,'QC Dump (clean)'!$L:$L,X$2,'QC Dump (clean)'!$M:$M,"Minor") -> 0 | Y9: =COUNTIFS('QC Dump (clean)'!$A:$A,$C9,'QC Dump (clean)'!$L:$L,Y$2,'QC Dump (clean)'!$M:$M,"Minor") -> 0 | Z9: =COUNTIFS('QC Dump (clean)'!$A:$A,$C9,'QC Dump (clean)'!$L:$L,Z$2,'QC Dump (clean)'!$M:$M,"Minor") -> 0 | AA9: =COUNTIFS('QC Dump (clean)'!$A:$A,$C9,'QC Dump (clean)'!$L:$L,AA$2,'QC Dump (clean)'!$M:$M,"Minor") -> 0 | AB9: =COUNTIFS('QC Dump (clean)'!$A:$A,$C9,'QC Dump (clean)'!$L:$L,AB$2,'QC Dump (clean)'!$M:$M,"Minor") -> 3 | ... AH9: =COUNTIFS('QC Dump (clean)'!$A:$A,$C9,'QC Dump (clean)'!$L:$L,AH$2,'QC Dump (clean)'!$M:$M,"Minor") -> 0 | AI9: =COUNTIFS('QC Dump (clean)'!$A:$A,$C9,'QC Dump (clean)'!$M:$M,"Unclassified") -> 0 | AJ9: =COUNTIFS('QC Dump (clean)'!$A:$A,$C9,'QC Dump (clean)'!$L:$L,AJ$2,'QC Dump (clean)'!$M:$M,"Unclassified") -> 0 | AK9: =COUNTIFS('QC Dump (clean)'!$A:$A,$C9,'QC Dump (clean)'!$H:$H,"Pending",'QC Dump (clean)'!$M:$M,"<>Not an error") -> 0 | AL9: =COUNTIFS('QC Dump (clean)'!$A:$A,$C9,'QC Dump (clean)'!$H:$H,"Resolved",'QC Dump (clean)'!$M:$M,"<>Not an error") -> 218 | AM9: =COUNTIFS('QC Dump (clean)'!$A:$A,$C9,'QC Dump (clean)'!$H:$H,"Ignore",'QC Dump (clean)'!$M:$M,"<>Not an error") -> 3 | AN9: =SUMIFS('QC Dump (clean)'!$S:$S,'QC Dump (clean)'!$A:$A,$C9) -> 56 | AO9: =IFERROR(AN9/$F9,"") -> 0.78873239 | AP9: =SUMIFS('QC Dump (clean)'!$T:$T,'QC Dump (clean)'!$A:$A,$C9) -> 54 | AQ9: =IFERROR(AP9/$F9,"") -> 0.76056338 | AR9: =SUMIFS('QC Dump (clean)'!$U:$U,'QC Dump (clean)'!$A:$A,$C9) -> 10 | AS9: =IFERROR(AR9/$F9,"") -> 0.14084507
A10: 8 | B10: His Secret Fortune | C10: edb3d0a58ac95f5ef497da24336396e996c6e7e9 | D10: Liebe Nach Vertrag | E10: Aug, Sept | F10: =IFERROR(VLOOKUP($C10,'Show IDs'!$A:$D,4,FALSE)+0,"") -> 200 | G10: =IFERROR(_xlfn.MINIFS('QC Dump (clean)'!$F:$F,'QC Dump (clean)'!$A:$A,$C10,'QC Dump (clean)'!$M:$M,"<>Not an error"),"") -> 2 | H10: =IFERROR(_xlfn.MAXIFS('QC Dump (clean)'!$F:$F,'QC Dump (clean)'!$A:$A,$C10,'QC Dump (clean)'!$M:$M,"<>Not an error"),"") -> 190 | J10: =L10+T10+AI10 -> 209 | K10: =IFERROR(J10/$F10,"") -> 1.045 | L10: =COUNTIFS('QC Dump (clean)'!$A:$A,$C10,'QC Dump (clean)'!$M:$M,"Major") -> 207 | M10: =COUNTIFS('QC Dump (clean)'!$A:$A,$C10,'QC Dump (clean)'!$L:$L,M$2,'QC Dump (clean)'!$M:$M,"Major") -> 0 | N10: =COUNTIFS('QC Dump (clean)'!$A:$A,$C10,'QC Dump (clean)'!$L:$L,N$2,'QC Dump (clean)'!$M:$M,"Major") -> 0 | O10: =COUNTIFS('QC Dump (clean)'!$A:$A,$C10,'QC Dump (clean)'!$L:$L,O$2,'QC Dump (clean)'!$M:$M,"Major") -> 6 | P10: =COUNTIFS('QC Dump (clean)'!$A:$A,$C10,'QC Dump (clean)'!$L:$L,P$2,'QC Dump (clean)'!$M:$M,"Major") -> 118 | Q10: =COUNTIFS('QC Dump (clean)'!$A:$A,$C10,'QC Dump (clean)'!$L:$L,Q$2,'QC Dump (clean)'!$M:$M,"Major") -> 75 | R10: =COUNTIFS('QC Dump (clean)'!$A:$A,$C10,'QC Dump (clean)'!$L:$L,R$2,'QC Dump (clean)'!$M:$M,"Major") -> 2 | S10: =COUNTIFS('QC Dump (clean)'!$A:$A,$C10,'QC Dump (clean)'!$L:$L,S$2,'QC Dump (clean)'!$M:$M,"Major") -> 6 | T10: =COUNTIFS('QC Dump (clean)'!$A:$A,$C10,'QC Dump (clean)'!$M:$M,"Minor") -> 2 | U10: =COUNTIFS('QC Dump (clean)'!$A:$A,$C10,'QC Dump (clean)'!$L:$L,U$2,'QC Dump (clean)'!$M:$M,"Minor") -> 0 | V10: =COUNTIFS('QC Dump (clean)'!$A:$A,$C10,'QC Dump (clean)'!$L:$L,V$2,'QC Dump (clean)'!$M:$M,"Minor") -> 0 | W10: =COUNTIFS('QC Dump (clean)'!$A:$A,$C10,'QC Dump (clean)'!$L:$L,W$2,'QC Dump (clean)'!$M:$M,"Minor") -> 0 | X10: =COUNTIFS('QC Dump (clean)'!$A:$A,$C10,'QC Dump (clean)'!$L:$L,X$2,'QC Dump (clean)'!$M:$M,"Minor") -> 0 | Y10: =COUNTIFS('QC Dump (clean)'!$A:$A,$C10,'QC Dump (clean)'!$L:$L,Y$2,'QC Dump (clean)'!$M:$M,"Minor") -> 0 | Z10: =COUNTIFS('QC Dump (clean)'!$A:$A,$C10,'QC Dump (clean)'!$L:$L,Z$2,'QC Dump (clean)'!$M:$M,"Minor") -> 0 | AA10: =COUNTIFS('QC Dump (clean)'!$A:$A,$C10,'QC Dump (clean)'!$L:$L,AA$2,'QC Dump (clean)'!$M:$M,"Minor") -> 1 | AB10: =COUNTIFS('QC Dump (clean)'!$A:$A,$C10,'QC Dump (clean)'!$L:$L,AB$2,'QC Dump (clean)'!$M:$M,"Minor") -> 0 | ... AH10: =COUNTIFS('QC Dump (clean)'!$A:$A,$C10,'QC Dump (clean)'!$L:$L,AH$2,'QC Dump (clean)'!$M:$M,"Minor") -> 1 | AI10: =COUNTIFS('QC Dump (clean)'!$A:$A,$C10,'QC Dump (clean)'!$M:$M,"Unclassified") -> 0 | AJ10: =COUNTIFS('QC Dump (clean)'!$A:$A,$C10,'QC Dump (clean)'!$L:$L,AJ$2,'QC Dump (clean)'!$M:$M,"Unclassified") -> 0 | AK10: =COUNTIFS('QC Dump (clean)'!$A:$A,$C10,'QC Dump (clean)'!$H:$H,"Pending",'QC Dump (clean)'!$M:$M,"<>Not an error") -> 0 | AL10: =COUNTIFS('QC Dump (clean)'!$A:$A,$C10,'QC Dump (clean)'!$H:$H,"Resolved",'QC Dump (clean)'!$M:$M,"<>Not an error") -> 111 | AM10: =COUNTIFS('QC Dump (clean)'!$A:$A,$C10,'QC Dump (clean)'!$H:$H,"Ignore",'QC Dump (clean)'!$M:$M,"<>Not an error") -> 98 | AN10: =SUMIFS('QC Dump (clean)'!$S:$S,'QC Dump (clean)'!$A:$A,$C10) -> 65 | AO10: =IFERROR(AN10/$F10,"") -> 0.325 | AP10: =SUMIFS('QC Dump (clean)'!$T:$T,'QC Dump (clean)'!$A:$A,$C10) -> 64 | AQ10: =IFERROR(AP10/$F10,"") -> 0.32 | AR10: =SUMIFS('QC Dump (clean)'!$U:$U,'QC Dump (clean)'!$A:$A,$C10) -> 2 | AS10: =IFERROR(AR10/$F10,"") -> 0.01
A11: 9 | B11: Bride of a dragon - BGM + SFX | C11: 2480d4767331b6a7bbbc4f588c705dd813a76a8d | D11: Bride of a Dragon (With BGM-SFX) | E11: Aug, Sept | F11: =IFERROR(VLOOKUP($C11,'Show IDs'!$A:$D,4,FALSE)+0,"") -> 100 | G11: =IFERROR(_xlfn.MINIFS('QC Dump (clean)'!$F:$F,'QC Dump (clean)'!$A:$A,$C11,'QC Dump (clean)'!$M:$M,"<>Not an error"),"") -> 1 | H11: =IFERROR(_xlfn.MAXIFS('QC Dump (clean)'!$F:$F,'QC Dump (clean)'!$A:$A,$C11,'QC Dump (clean)'!$M:$M,"<>Not an error"),"") -> 100 | J11: =L11+T11+AI11 -> 177 | K11: =IFERROR(J11/$F11,"") -> 1.77 | L11: =COUNTIFS('QC Dump (clean)'!$A:$A,$C11,'QC Dump (clean)'!$M:$M,"Major") -> 164 | M11: =COUNTIFS('QC Dump (clean)'!$A:$A,$C11,'QC Dump (clean)'!$L:$L,M$2,'QC Dump (clean)'!$M:$M,"Major") -> 0 | N11: =COUNTIFS('QC Dump (clean)'!$A:$A,$C11,'QC Dump (clean)'!$L:$L,N$2,'QC Dump (clean)'!$M:$M,"Major") -> 0 | O11: =COUNTIFS('QC Dump (clean)'!$A:$A,$C11,'QC Dump (clean)'!$L:$L,O$2,'QC Dump (clean)'!$M:$M,"Major") -> 0 | P11: =COUNTIFS('QC Dump (clean)'!$A:$A,$C11,'QC Dump (clean)'!$L:$L,P$2,'QC Dump (clean)'!$M:$M,"Major") -> 0 | Q11: =COUNTIFS('QC Dump (clean)'!$A:$A,$C11,'QC Dump (clean)'!$L:$L,Q$2,'QC Dump (clean)'!$M:$M,"Major") -> 127 | R11: =COUNTIFS('QC Dump (clean)'!$A:$A,$C11,'QC Dump (clean)'!$L:$L,R$2,'QC Dump (clean)'!$M:$M,"Major") -> 0 | S11: =COUNTIFS('QC Dump (clean)'!$A:$A,$C11,'QC Dump (clean)'!$L:$L,S$2,'QC Dump (clean)'!$M:$M,"Major") -> 37 | T11: =COUNTIFS('QC Dump (clean)'!$A:$A,$C11,'QC Dump (clean)'!$M:$M,"Minor") -> 13 | U11: =COUNTIFS('QC Dump (clean)'!$A:$A,$C11,'QC Dump (clean)'!$L:$L,U$2,'QC Dump (clean)'!$M:$M,"Minor") -> 12 | V11: =COUNTIFS('QC Dump (clean)'!$A:$A,$C11,'QC Dump (clean)'!$L:$L,V$2,'QC Dump (clean)'!$M:$M,"Minor") -> 0 | W11: =COUNTIFS('QC Dump (clean)'!$A:$A,$C11,'QC Dump (clean)'!$L:$L,W$2,'QC Dump (clean)'!$M:$M,"Minor") -> 0 | X11: =COUNTIFS('QC Dump (clean)'!$A:$A,$C11,'QC Dump (clean)'!$L:$L,X$2,'QC Dump (clean)'!$M:$M,"Minor") -> 0 | Y11: =COUNTIFS('QC Dump (clean)'!$A:$A,$C11,'QC Dump (clean)'!$L:$L,Y$2,'QC Dump (clean)'!$M:$M,"Minor") -> 0 | Z11: =COUNTIFS('QC Dump (clean)'!$A:$A,$C11,'QC Dump (clean)'!$L:$L,Z$2,'QC Dump (clean)'!$M:$M,"Minor") -> 0 | AA11: =COUNTIFS('QC Dump (clean)'!$A:$A,$C11,'QC Dump (clean)'!$L:$L,AA$2,'QC Dump (clean)'!$M:$M,"Minor") -> 0 | AB11: =COUNTIFS('QC Dump (clean)'!$A:$A,$C11,'QC Dump (clean)'!$L:$L,AB$2,'QC Dump (clean)'!$M:$M,"Minor") -> 1 | ... AH11: =COUNTIFS('QC Dump (clean)'!$A:$A,$C11,'QC Dump (clean)'!$L:$L,AH$2,'QC Dump (clean)'!$M:$M,"Minor") -> 0 | AI11: =COUNTIFS('QC Dump (clean)'!$A:$A,$C11,'QC Dump (clean)'!$M:$M,"Unclassified") -> 0 | AJ11: =COUNTIFS('QC Dump (clean)'!$A:$A,$C11,'QC Dump (clean)'!$L:$L,AJ$2,'QC Dump (clean)'!$M:$M,"Unclassified") -> 0 | AK11: =COUNTIFS('QC Dump (clean)'!$A:$A,$C11,'QC Dump (clean)'!$H:$H,"Pending",'QC Dump (clean)'!$M:$M,"<>Not an error") -> 177 | AL11: =COUNTIFS('QC Dump (clean)'!$A:$A,$C11,'QC Dump (clean)'!$H:$H,"Resolved",'QC Dump (clean)'!$M:$M,"<>Not an error") -> 0 | AM11: =COUNTIFS('QC Dump (clean)'!$A:$A,$C11,'QC Dump (clean)'!$H:$H,"Ignore",'QC Dump (clean)'!$M:$M,"<>Not an error") -> 0 | AN11: =SUMIFS('QC Dump (clean)'!$S:$S,'QC Dump (clean)'!$A:$A,$C11) -> 69 | AO11: =IFERROR(AN11/$F11,"") -> 0.69 | AP11: =SUMIFS('QC Dump (clean)'!$T:$T,'QC Dump (clean)'!$A:$A,$C11) -> 68 | AQ11: =IFERROR(AP11/$F11,"") -> 0.68 | AR11: =SUMIFS('QC Dump (clean)'!$U:$U,'QC Dump (clean)'!$A:$A,$C11) -> 10 | AS11: =IFERROR(AR11/$F11,"") -> 0.1
A12: 10 | B12: Rise of the Beastmaster | C12: af2d64963a0b2a4ae6e1645ebec6e6220c089166 | D12: Der Aufstieg Des Beastmasters | E12: Aug, Sept | F12: =IFERROR(VLOOKUP($C12,'Show IDs'!$A:$D,4,FALSE)+0,"") -> 75 | G12: =IFERROR(_xlfn.MINIFS('QC Dump (clean)'!$F:$F,'QC Dump (clean)'!$A:$A,$C12,'QC Dump (clean)'!$M:$M,"<>Not an error"),"") -> 1 | H12: =IFERROR(_xlfn.MAXIFS('QC Dump (clean)'!$F:$F,'QC Dump (clean)'!$A:$A,$C12,'QC Dump (clean)'!$M:$M,"<>Not an error"),"") -> 73 | J12: =L12+T12+AI12 -> 171 | K12: =IFERROR(J12/$F12,"") -> 2.28 | L12: =COUNTIFS('QC Dump (clean)'!$A:$A,$C12,'QC Dump (clean)'!$M:$M,"Major") -> 169 | M12: =COUNTIFS('QC Dump (clean)'!$A:$A,$C12,'QC Dump (clean)'!$L:$L,M$2,'QC Dump (clean)'!$M:$M,"Major") -> 0 | N12: =COUNTIFS('QC Dump (clean)'!$A:$A,$C12,'QC Dump (clean)'!$L:$L,N$2,'QC Dump (clean)'!$M:$M,"Major") -> 0 | O12: =COUNTIFS('QC Dump (clean)'!$A:$A,$C12,'QC Dump (clean)'!$L:$L,O$2,'QC Dump (clean)'!$M:$M,"Major") -> 0 | P12: =COUNTIFS('QC Dump (clean)'!$A:$A,$C12,'QC Dump (clean)'!$L:$L,P$2,'QC Dump (clean)'!$M:$M,"Major") -> 0 | Q12: =COUNTIFS('QC Dump (clean)'!$A:$A,$C12,'QC Dump (clean)'!$L:$L,Q$2,'QC Dump (clean)'!$M:$M,"Major") -> 12 | R12: =COUNTIFS('QC Dump (clean)'!$A:$A,$C12,'QC Dump (clean)'!$L:$L,R$2,'QC Dump (clean)'!$M:$M,"Major") -> 0 | S12: =COUNTIFS('QC Dump (clean)'!$A:$A,$C12,'QC Dump (clean)'!$L:$L,S$2,'QC Dump (clean)'!$M:$M,"Major") -> 157 | T12: =COUNTIFS('QC Dump (clean)'!$A:$A,$C12,'QC Dump (clean)'!$M:$M,"Minor") -> 2 | U12: =COUNTIFS('QC Dump (clean)'!$A:$A,$C12,'QC Dump (clean)'!$L:$L,U$2,'QC Dump (clean)'!$M:$M,"Minor") -> 0 | V12: =COUNTIFS('QC Dump (clean)'!$A:$A,$C12,'QC Dump (clean)'!$L:$L,V$2,'QC Dump (clean)'!$M:$M,"Minor") -> 1 | W12: =COUNTIFS('QC Dump (clean)'!$A:$A,$C12,'QC Dump (clean)'!$L:$L,W$2,'QC Dump (clean)'!$M:$M,"Minor") -> 0 | X12: =COUNTIFS('QC Dump (clean)'!$A:$A,$C12,'QC Dump (clean)'!$L:$L,X$2,'QC Dump (clean)'!$M:$M,"Minor") -> 0 | Y12: =COUNTIFS('QC Dump (clean)'!$A:$A,$C12,'QC Dump (clean)'!$L:$L,Y$2,'QC Dump (clean)'!$M:$M,"Minor") -> 0 | Z12: =COUNTIFS('QC Dump (clean)'!$A:$A,$C12,'QC Dump (clean)'!$L:$L,Z$2,'QC Dump (clean)'!$M:$M,"Minor") -> 0 | AA12: =COUNTIFS('QC Dump (clean)'!$A:$A,$C12,'QC Dump (clean)'!$L:$L,AA$2,'QC Dump (clean)'!$M:$M,"Minor") -> 0 | AB12: =COUNTIFS('QC Dump (clean)'!$A:$A,$C12,'QC Dump (clean)'!$L:$L,AB$2,'QC Dump (clean)'!$M:$M,"Minor") -> 1 | ... AH12: =COUNTIFS('QC Dump (clean)'!$A:$A,$C12,'QC Dump (clean)'!$L:$L,AH$2,'QC Dump (clean)'!$M:$M,"Minor") -> 0 | AI12: =COUNTIFS('QC Dump (clean)'!$A:$A,$C12,'QC Dump (clean)'!$M:$M,"Unclassified") -> 0 | AJ12: =COUNTIFS('QC Dump (clean)'!$A:$A,$C12,'QC Dump (clean)'!$L:$L,AJ$2,'QC Dump (clean)'!$M:$M,"Unclassified") -> 0 | AK12: =COUNTIFS('QC Dump (clean)'!$A:$A,$C12,'QC Dump (clean)'!$H:$H,"Pending",'QC Dump (clean)'!$M:$M,"<>Not an error") -> 3 | AL12: =COUNTIFS('QC Dump (clean)'!$A:$A,$C12,'QC Dump (clean)'!$H:$H,"Resolved",'QC Dump (clean)'!$M:$M,"<>Not an error") -> 167 | AM12: =COUNTIFS('QC Dump (clean)'!$A:$A,$C12,'QC Dump (clean)'!$H:$H,"Ignore",'QC Dump (clean)'!$M:$M,"<>Not an error") -> 1 | AN12: =SUMIFS('QC Dump (clean)'!$S:$S,'QC Dump (clean)'!$A:$A,$C12) -> 60 | AO12: =IFERROR(AN12/$F12,"") -> 0.8 | AP12: =SUMIFS('QC Dump (clean)'!$T:$T,'QC Dump (clean)'!$A:$A,$C12) -> 60 | AQ12: =IFERROR(AP12/$F12,"") -> 0.8 | AR12: =SUMIFS('QC Dump (clean)'!$U:$U,'QC Dump (clean)'!$A:$A,$C12) -> 2 | AS12: =IFERROR(AR12/$F12,"") -> 0.026666667
A13: 11 | B13: Ashes to crown | C13: 783983a98fe2613f15770fa78630e1d8965712e2 | D13: Aus Der Asche Zur Krone | E13: Aug | F13: =IFERROR(VLOOKUP($C13,'Show IDs'!$A:$D,4,FALSE)+0,"") -> 80 | G13: =IFERROR(_xlfn.MINIFS('QC Dump (clean)'!$F:$F,'QC Dump (clean)'!$A:$A,$C13,'QC Dump (clean)'!$M:$M,"<>Not an error"),"") -> 1 | H13: =IFERROR(_xlfn.MAXIFS('QC Dump (clean)'!$F:$F,'QC Dump (clean)'!$A:$A,$C13,'QC Dump (clean)'!$M:$M,"<>Not an error"),"") -> 80 | J13: =L13+T13+AI13 -> 141 | K13: =IFERROR(J13/$F13,"") -> 1.7625 | L13: =COUNTIFS('QC Dump (clean)'!$A:$A,$C13,'QC Dump (clean)'!$M:$M,"Major") -> 141 | M13: =COUNTIFS('QC Dump (clean)'!$A:$A,$C13,'QC Dump (clean)'!$L:$L,M$2,'QC Dump (clean)'!$M:$M,"Major") -> 1 | N13: =COUNTIFS('QC Dump (clean)'!$A:$A,$C13,'QC Dump (clean)'!$L:$L,N$2,'QC Dump (clean)'!$M:$M,"Major") -> 0 | O13: =COUNTIFS('QC Dump (clean)'!$A:$A,$C13,'QC Dump (clean)'!$L:$L,O$2,'QC Dump (clean)'!$M:$M,"Major") -> 0 | P13: =COUNTIFS('QC Dump (clean)'!$A:$A,$C13,'QC Dump (clean)'!$L:$L,P$2,'QC Dump (clean)'!$M:$M,"Major") -> 0 | Q13: =COUNTIFS('QC Dump (clean)'!$A:$A,$C13,'QC Dump (clean)'!$L:$L,Q$2,'QC Dump (clean)'!$M:$M,"Major") -> 123 | R13: =COUNTIFS('QC Dump (clean)'!$A:$A,$C13,'QC Dump (clean)'!$L:$L,R$2,'QC Dump (clean)'!$M:$M,"Major") -> 0 | S13: =COUNTIFS('QC Dump (clean)'!$A:$A,$C13,'QC Dump (clean)'!$L:$L,S$2,'QC Dump (clean)'!$M:$M,"Major") -> 17 | T13: =COUNTIFS('QC Dump (clean)'!$A:$A,$C13,'QC Dump (clean)'!$M:$M,"Minor") -> 0 | U13: =COUNTIFS('QC Dump (clean)'!$A:$A,$C13,'QC Dump (clean)'!$L:$L,U$2,'QC Dump (clean)'!$M:$M,"Minor") -> 0 | V13: =COUNTIFS('QC Dump (clean)'!$A:$A,$C13,'QC Dump (clean)'!$L:$L,V$2,'QC Dump (clean)'!$M:$M,"Minor") -> 0 | W13: =COUNTIFS('QC Dump (clean)'!$A:$A,$C13,'QC Dump (clean)'!$L:$L,W$2,'QC Dump (clean)'!$M:$M,"Minor") -> 0 | X13: =COUNTIFS('QC Dump (clean)'!$A:$A,$C13,'QC Dump (clean)'!$L:$L,X$2,'QC Dump (clean)'!$M:$M,"Minor") -> 0 | Y13: =COUNTIFS('QC Dump (clean)'!$A:$A,$C13,'QC Dump (clean)'!$L:$L,Y$2,'QC Dump (clean)'!$M:$M,"Minor") -> 0 | Z13: =COUNTIFS('QC Dump (clean)'!$A:$A,$C13,'QC Dump (clean)'!$L:$L,Z$2,'QC Dump (clean)'!$M:$M,"Minor") -> 0 | AA13: =COUNTIFS('QC Dump (clean)'!$A:$A,$C13,'QC Dump (clean)'!$L:$L,AA$2,'QC Dump (clean)'!$M:$M,"Minor") -> 0 | AB13: =COUNTIFS('QC Dump (clean)'!$A:$A,$C13,'QC Dump (clean)'!$L:$L,AB$2,'QC Dump (clean)'!$M:$M,"Minor") -> 0 | ... AH13: =COUNTIFS('QC Dump (clean)'!$A:$A,$C13,'QC Dump (clean)'!$L:$L,AH$2,'QC Dump (clean)'!$M:$M,"Minor") -> 0 | AI13: =COUNTIFS('QC Dump (clean)'!$A:$A,$C13,'QC Dump (clean)'!$M:$M,"Unclassified") -> 0 | AJ13: =COUNTIFS('QC Dump (clean)'!$A:$A,$C13,'QC Dump (clean)'!$L:$L,AJ$2,'QC Dump (clean)'!$M:$M,"Unclassified") -> 0 | AK13: =COUNTIFS('QC Dump (clean)'!$A:$A,$C13,'QC Dump (clean)'!$H:$H,"Pending",'QC Dump (clean)'!$M:$M,"<>Not an error") -> 1 | AL13: =COUNTIFS('QC Dump (clean)'!$A:$A,$C13,'QC Dump (clean)'!$H:$H,"Resolved",'QC Dump (clean)'!$M:$M,"<>Not an error") -> 139 | AM13: =COUNTIFS('QC Dump (clean)'!$A:$A,$C13,'QC Dump (clean)'!$H:$H,"Ignore",'QC Dump (clean)'!$M:$M,"<>Not an error") -> 1 | AN13: =SUMIFS('QC Dump (clean)'!$S:$S,'QC Dump (clean)'!$A:$A,$C13) -> 52 | AO13: =IFERROR(AN13/$F13,"") -> 0.65 | AP13: =SUMIFS('QC Dump (clean)'!$T:$T,'QC Dump (clean)'!$A:$A,$C13) -> 52 | AQ13: =IFERROR(AP13/$F13,"") -> 0.65 | AR13: =SUMIFS('QC Dump (clean)'!$U:$U,'QC Dump (clean)'!$A:$A,$C13) -> 0 | AS13: =IFERROR(AR13/$F13,"") -> 0
A14: 12 | B14: Mad Vampire Lord's Bride | C14: 9540fa0b0f0a4e67296efcd05e977d34ff2d48cc | D14: Die Braut Des Wahnsinnigen Vampirfürsten | E14: Aug, Sept | F14: =IFERROR(VLOOKUP($C14,'Show IDs'!$A:$D,4,FALSE)+0,"") -> 564 | G14: =IFERROR(_xlfn.MINIFS('QC Dump (clean)'!$F:$F,'QC Dump (clean)'!$A:$A,$C14,'QC Dump (clean)'!$M:$M,"<>Not an error"),"") -> 28 | H14: =IFERROR(_xlfn.MAXIFS('QC Dump (clean)'!$F:$F,'QC Dump (clean)'!$A:$A,$C14,'QC Dump (clean)'!$M:$M,"<>Not an error"),"") -> 563 | J14: =L14+T14+AI14 -> 122 | K14: =IFERROR(J14/$F14,"") -> 0.21631206 | L14: =COUNTIFS('QC Dump (clean)'!$A:$A,$C14,'QC Dump (clean)'!$M:$M,"Major") -> 122 | M14: =COUNTIFS('QC Dump (clean)'!$A:$A,$C14,'QC Dump (clean)'!$L:$L,M$2,'QC Dump (clean)'!$M:$M,"Major") -> 0 | N14: =COUNTIFS('QC Dump (clean)'!$A:$A,$C14,'QC Dump (clean)'!$L:$L,N$2,'QC Dump (clean)'!$M:$M,"Major") -> 0 | O14: =COUNTIFS('QC Dump (clean)'!$A:$A,$C14,'QC Dump (clean)'!$L:$L,O$2,'QC Dump (clean)'!$M:$M,"Major") -> 0 | P14: =COUNTIFS('QC Dump (clean)'!$A:$A,$C14,'QC Dump (clean)'!$L:$L,P$2,'QC Dump (clean)'!$M:$M,"Major") -> 0 | Q14: =COUNTIFS('QC Dump (clean)'!$A:$A,$C14,'QC Dump (clean)'!$L:$L,Q$2,'QC Dump (clean)'!$M:$M,"Major") -> 56 | R14: =COUNTIFS('QC Dump (clean)'!$A:$A,$C14,'QC Dump (clean)'!$L:$L,R$2,'QC Dump (clean)'!$M:$M,"Major") -> 0 | S14: =COUNTIFS('QC Dump (clean)'!$A:$A,$C14,'QC Dump (clean)'!$L:$L,S$2,'QC Dump (clean)'!$M:$M,"Major") -> 66 | T14: =COUNTIFS('QC Dump (clean)'!$A:$A,$C14,'QC Dump (clean)'!$M:$M,"Minor") -> 0 | U14: =COUNTIFS('QC Dump (clean)'!$A:$A,$C14,'QC Dump (clean)'!$L:$L,U$2,'QC Dump (clean)'!$M:$M,"Minor") -> 0 | V14: =COUNTIFS('QC Dump (clean)'!$A:$A,$C14,'QC Dump (clean)'!$L:$L,V$2,'QC Dump (clean)'!$M:$M,"Minor") -> 0 | W14: =COUNTIFS('QC Dump (clean)'!$A:$A,$C14,'QC Dump (clean)'!$L:$L,W$2,'QC Dump (clean)'!$M:$M,"Minor") -> 0 | X14: =COUNTIFS('QC Dump (clean)'!$A:$A,$C14,'QC Dump (clean)'!$L:$L,X$2,'QC Dump (clean)'!$M:$M,"Minor") -> 0 | Y14: =COUNTIFS('QC Dump (clean)'!$A:$A,$C14,'QC Dump (clean)'!$L:$L,Y$2,'QC Dump (clean)'!$M:$M,"Minor") -> 0 | Z14: =COUNTIFS('QC Dump (clean)'!$A:$A,$C14,'QC Dump (clean)'!$L:$L,Z$2,'QC Dump (clean)'!$M:$M,"Minor") -> 0 | AA14: =COUNTIFS('QC Dump (clean)'!$A:$A,$C14,'QC Dump (clean)'!$L:$L,AA$2,'QC Dump (clean)'!$M:$M,"Minor") -> 0 | AB14: =COUNTIFS('QC Dump (clean)'!$A:$A,$C14,'QC Dump (clean)'!$L:$L,AB$2,'QC Dump (clean)'!$M:$M,"Minor") -> 0 | ... AH14: =COUNTIFS('QC Dump (clean)'!$A:$A,$C14,'QC Dump (clean)'!$L:$L,AH$2,'QC Dump (clean)'!$M:$M,"Minor") -> 0 | AI14: =COUNTIFS('QC Dump (clean)'!$A:$A,$C14,'QC Dump (clean)'!$M:$M,"Unclassified") -> 0 | AJ14: =COUNTIFS('QC Dump (clean)'!$A:$A,$C14,'QC Dump (clean)'!$L:$L,AJ$2,'QC Dump (clean)'!$M:$M,"Unclassified") -> 0 | AK14: =COUNTIFS('QC Dump (clean)'!$A:$A,$C14,'QC Dump (clean)'!$H:$H,"Pending",'QC Dump (clean)'!$M:$M,"<>Not an error") -> 0 | AL14: =COUNTIFS('QC Dump (clean)'!$A:$A,$C14,'QC Dump (clean)'!$H:$H,"Resolved",'QC Dump (clean)'!$M:$M,"<>Not an error") -> 117 | AM14: =COUNTIFS('QC Dump (clean)'!$A:$A,$C14,'QC Dump (clean)'!$H:$H,"Ignore",'QC Dump (clean)'!$M:$M,"<>Not an error") -> 5 | AN14: =SUMIFS('QC Dump (clean)'!$S:$S,'QC Dump (clean)'!$A:$A,$C14) -> 51 | AO14: =IFERROR(AN14/$F14,"") -> 0.090425532 | AP14: =SUMIFS('QC Dump (clean)'!$T:$T,'QC Dump (clean)'!$A:$A,$C14) -> 51 | AQ14: =IFERROR(AP14/$F14,"") -> 0.090425532 | AR14: =SUMIFS('QC Dump (clean)'!$U:$U,'QC Dump (clean)'!$A:$A,$C14) -> 0 | AS14: =IFERROR(AR14/$F14,"") -> 0
... A41: 39 | B41: The Outcast's Rise | C41: 7b1f3211cfdfae355799078a0b675eb572c9f339 | D41: Der Aufstieg Des Verstoßenen | E41: Sept | F41: =IFERROR(VLOOKUP($C41,'Show IDs'!$A:$D,4,FALSE)+0,"") -> 130 | G41: =IFERROR(_xlfn.MINIFS('QC Dump (clean)'!$F:$F,'QC Dump (clean)'!$A:$A,$C41,'QC Dump (clean)'!$M:$M,"<>Not an error"),"") -> 50 | H41: =IFERROR(_xlfn.MAXIFS('QC Dump (clean)'!$F:$F,'QC Dump (clean)'!$A:$A,$C41,'QC Dump (clean)'!$M:$M,"<>Not an error"),"") -> 50 | J41: =L41+T41+AI41 -> 1 | K41: =IFERROR(J41/$F41,"") -> 0.0076923077 | L41: =COUNTIFS('QC Dump (clean)'!$A:$A,$C41,'QC Dump (clean)'!$M:$M,"Major") -> 1 | M41: =COUNTIFS('QC Dump (clean)'!$A:$A,$C41,'QC Dump (clean)'!$L:$L,M$2,'QC Dump (clean)'!$M:$M,"Major") -> 0 | N41: =COUNTIFS('QC Dump (clean)'!$A:$A,$C41,'QC Dump (clean)'!$L:$L,N$2,'QC Dump (clean)'!$M:$M,"Major") -> 0 | O41: =COUNTIFS('QC Dump (clean)'!$A:$A,$C41,'QC Dump (clean)'!$L:$L,O$2,'QC Dump (clean)'!$M:$M,"Major") -> 0 | P41: =COUNTIFS('QC Dump (clean)'!$A:$A,$C41,'QC Dump (clean)'!$L:$L,P$2,'QC Dump (clean)'!$M:$M,"Major") -> 0 | Q41: =COUNTIFS('QC Dump (clean)'!$A:$A,$C41,'QC Dump (clean)'!$L:$L,Q$2,'QC Dump (clean)'!$M:$M,"Major") -> 1 | R41: =COUNTIFS('QC Dump (clean)'!$A:$A,$C41,'QC Dump (clean)'!$L:$L,R$2,'QC Dump (clean)'!$M:$M,"Major") -> 0 | S41: =COUNTIFS('QC Dump (clean)'!$A:$A,$C41,'QC Dump (clean)'!$L:$L,S$2,'QC Dump (clean)'!$M:$M,"Major") -> 0 | T41: =COUNTIFS('QC Dump (clean)'!$A:$A,$C41,'QC Dump (clean)'!$M:$M,"Minor") -> 0 | U41: =COUNTIFS('QC Dump (clean)'!$A:$A,$C41,'QC Dump (clean)'!$L:$L,U$2,'QC Dump (clean)'!$M:$M,"Minor") -> 0 | V41: =COUNTIFS('QC Dump (clean)'!$A:$A,$C41,'QC Dump (clean)'!$L:$L,V$2,'QC Dump (clean)'!$M:$M,"Minor") -> 0 | W41: =COUNTIFS('QC Dump (clean)'!$A:$A,$C41,'QC Dump (clean)'!$L:$L,W$2,'QC Dump (clean)'!$M:$M,"Minor") -> 0 | X41: =COUNTIFS('QC Dump (clean)'!$A:$A,$C41,'QC Dump (clean)'!$L:$L,X$2,'QC Dump (clean)'!$M:$M,"Minor") -> 0 | Y41: =COUNTIFS('QC Dump (clean)'!$A:$A,$C41,'QC Dump (clean)'!$L:$L,Y$2,'QC Dump (clean)'!$M:$M,"Minor") -> 0 | Z41: =COUNTIFS('QC Dump (clean)'!$A:$A,$C41,'QC Dump (clean)'!$L:$L,Z$2,'QC Dump (clean)'!$M:$M,"Minor") -> 0 | AA41: =COUNTIFS('QC Dump (clean)'!$A:$A,$C41,'QC Dump (clean)'!$L:$L,AA$2,'QC Dump (clean)'!$M:$M,"Minor") -> 0 | AB41: =COUNTIFS('QC Dump (clean)'!$A:$A,$C41,'QC Dump (clean)'!$L:$L,AB$2,'QC Dump (clean)'!$M:$M,"Minor") -> 0 | ... AH41: =COUNTIFS('QC Dump (clean)'!$A:$A,$C41,'QC Dump (clean)'!$L:$L,AH$2,'QC Dump (clean)'!$M:$M,"Minor") -> 0 | AI41: =COUNTIFS('QC Dump (clean)'!$A:$A,$C41,'QC Dump (clean)'!$M:$M,"Unclassified") -> 0 | AJ41: =COUNTIFS('QC Dump (clean)'!$A:$A,$C41,'QC Dump (clean)'!$L:$L,AJ$2,'QC Dump (clean)'!$M:$M,"Unclassified") -> 0 | AK41: =COUNTIFS('QC Dump (clean)'!$A:$A,$C41,'QC Dump (clean)'!$H:$H,"Pending",'QC Dump (clean)'!$M:$M,"<>Not an error") -> 1 | AL41: =COUNTIFS('QC Dump (clean)'!$A:$A,$C41,'QC Dump (clean)'!$H:$H,"Resolved",'QC Dump (clean)'!$M:$M,"<>Not an error") -> 0 | AM41: =COUNTIFS('QC Dump (clean)'!$A:$A,$C41,'QC Dump (clean)'!$H:$H,"Ignore",'QC Dump (clean)'!$M:$M,"<>Not an error") -> 0 | AN41: =SUMIFS('QC Dump (clean)'!$S:$S,'QC Dump (clean)'!$A:$A,$C41) -> 1 | AO41: =IFERROR(AN41/$F41,"") -> 0.0076923077 | AP41: =SUMIFS('QC Dump (clean)'!$T:$T,'QC Dump (clean)'!$A:$A,$C41) -> 1 | AQ41: =IFERROR(AP41/$F41,"") -> 0.0076923077 | AR41: =SUMIFS('QC Dump (clean)'!$U:$U,'QC Dump (clean)'!$A:$A,$C41) -> 0 | AS41: =IFERROR(AR41/$F41,"") -> 0
B42: Total | F42: =SUM(F3:F41) -> 4226 | J42: =SUM(J3:J41) -> 5838 | K42: =IFERROR(SUMIFS(J3:J41,$F3:$F41,">0")/F42,"") | L42: =SUM(L3:L41) -> 5584 | M42: =SUM(M3:M41) -> 16 | N42: =SUM(N3:N41) -> 49 | O42: =SUM(O3:O41) -> 14 | P42: =SUM(P3:P41) -> 169 | Q42: =SUM(Q3:Q41) -> 1776 | R42: =SUM(R3:R41) -> 8 | S42: =SUM(S3:S41) -> 3552 | ... AN42: =SUM(AN3:AN41) -> 1541 | AO42: =IFERROR(SUMIFS(AN3:AN41,$F3:$F41,">0")/F42,"") | AP42: =SUM(AP3:AP41) -> 1463 | AQ42: =IFERROR(SUMIFS(AP3:AP41,$F3:$F41,">0")/F42,"") | AR42: =SUM(AR3:AR41) -> 209 | AS42: =IFERROR(SUMIFS(AR3:AR41,$F3:$F41,">0")/F42,"")

Sheet Monthly
A1: Severity | B1: Issue type | C1: 2026-08 (Aug) | D1: 2026-09 (Sept) | E1: Total
A2: Major | B2: All Major | C2: =COUNTIFS('QC Dump (clean)'!$M:$M,$A2,'QC Dump (clean)'!$R:$R,C$1) -> 1863 | D2: =COUNTIFS('QC Dump (clean)'!$M:$M,$A2,'QC Dump (clean)'!$R:$R,D$1) -> 3721 | E2: =SUM(C2:D2)
A3: Major | B3: Abrupt cut / Jerk | C3: =COUNTIFS('QC Dump (clean)'!$L:$L,$B3,'QC Dump (clean)'!$M:$M,$A3,'QC Dump (clean)'!$R:$R,C$1) -> 6 | D3: =COUNTIFS('QC Dump (clean)'!$L:$L,$B3,'QC Dump (clean)'!$M:$M,$A3,'QC Dump (clean)'!$R:$R,D$1) -> 10 | E3: =SUM(C3:D3)
A4: Major | B4: Audio quality | C4: =COUNTIFS('QC Dump (clean)'!$L:$L,$B4,'QC Dump (clean)'!$M:$M,$A4,'QC Dump (clean)'!$R:$R,C$1) -> 29 | D4: =COUNTIFS('QC Dump (clean)'!$L:$L,$B4,'QC Dump (clean)'!$M:$M,$A4,'QC Dump (clean)'!$R:$R,D$1) -> 20 | E4: =SUM(C4:D4)
A5: Major | B5: Gramatically incorrect (voa) | C5: =COUNTIFS('QC Dump (clean)'!$L:$L,$B5,'QC Dump (clean)'!$M:$M,$A5,'QC Dump (clean)'!$R:$R,C$1) -> 4 | D5: =COUNTIFS('QC Dump (clean)'!$L:$L,$B5,'QC Dump (clean)'!$M:$M,$A5,'QC Dump (clean)'!$R:$R,D$1) -> 10 | E5: =SUM(C5:D5)
A6: Major | B6: Incorrect name | C6: =COUNTIFS('QC Dump (clean)'!$L:$L,$B6,'QC Dump (clean)'!$M:$M,$A6,'QC Dump (clean)'!$R:$R,C$1) -> 100 | D6: =COUNTIFS('QC Dump (clean)'!$L:$L,$B6,'QC Dump (clean)'!$M:$M,$A6,'QC Dump (clean)'!$R:$R,D$1) -> 69 | E6: =SUM(C6:D6)
A7: Major | B7: Mispronunciation | C7: =COUNTIFS('QC Dump (clean)'!$L:$L,$B7,'QC Dump (clean)'!$M:$M,$A7,'QC Dump (clean)'!$R:$R,C$1) -> 688 | D7: =COUNTIFS('QC Dump (clean)'!$L:$L,$B7,'QC Dump (clean)'!$M:$M,$A7,'QC Dump (clean)'!$R:$R,D$1) -> 1088 | E7: =SUM(C7:D7)
A8: Major | B8: Missed line / Word | C8: =COUNTIFS('QC Dump (clean)'!$L:$L,$B8,'QC Dump (clean)'!$M:$M,$A8,'QC Dump (clean)'!$R:$R,C$1) -> 3 | D8: =COUNTIFS('QC Dump (clean)'!$L:$L,$B8,'QC Dump (clean)'!$M:$M,$A8,'QC Dump (clean)'!$R:$R,D$1) -> 5 | E8: =SUM(C8:D8)
A9: Major | B9: Script error | C9: =COUNTIFS('QC Dump (clean)'!$L:$L,$B9,'QC Dump (clean)'!$M:$M,$A9,'QC Dump (clean)'!$R:$R,C$1) -> 1033 | D9: =COUNTIFS('QC Dump (clean)'!$L:$L,$B9,'QC Dump (clean)'!$M:$M,$A9,'QC Dump (clean)'!$R:$R,D$1) -> 2519 | E9: =SUM(C9:D9)
A10: Minor | B10: All Minor | C10: =COUNTIFS('QC Dump (clean)'!$M:$M,$A10,'QC Dump (clean)'!$R:$R,C$1) -> 72 | D10: =COUNTIFS('QC Dump (clean)'!$M:$M,$A10,'QC Dump (clean)'!$R:$R,D$1) -> 180 | E10: =SUM(C10:D10)
A11: Minor | B11: Acting | C11: =COUNTIFS('QC Dump (clean)'!$L:$L,$B11,'QC Dump (clean)'!$M:$M,$A11,'QC Dump (clean)'!$R:$R,C$1) -> 30 | D11: =COUNTIFS('QC Dump (clean)'!$L:$L,$B11,'QC Dump (clean)'!$M:$M,$A11,'QC Dump (clean)'!$R:$R,D$1) -> 19 | E11: =SUM(C11:D11)
A12: Minor | B12: Audio Regenerated | C12: =COUNTIFS('QC Dump (clean)'!$L:$L,$B12,'QC Dump (clean)'!$M:$M,$A12,'QC Dump (clean)'!$R:$R,C$1) -> 1 | D12: =COUNTIFS('QC Dump (clean)'!$L:$L,$B12,'QC Dump (clean)'!$M:$M,$A12,'QC Dump (clean)'!$R:$R,D$1) -> 5 | E12: =SUM(C12:D12)
A13: Minor | B13: Background noise | C13: =COUNTIFS('QC Dump (clean)'!$L:$L,$B13,'QC Dump (clean)'!$M:$M,$A13,'QC Dump (clean)'!$R:$R,C$1) -> 0 | D13: =COUNTIFS('QC Dump (clean)'!$L:$L,$B13,'QC Dump (clean)'!$M:$M,$A13,'QC Dump (clean)'!$R:$R,D$1) -> 10 | E13: =SUM(C13:D13)
A14: Minor | B14: Breathing noise | C14: =COUNTIFS('QC Dump (clean)'!$L:$L,$B14,'QC Dump (clean)'!$M:$M,$A14,'QC Dump (clean)'!$R:$R,C$1) -> 0 | D14: =COUNTIFS('QC Dump (clean)'!$L:$L,$B14,'QC Dump (clean)'!$M:$M,$A14,'QC Dump (clean)'!$R:$R,D$1) -> 3 | E14: =SUM(C14:D14)
A15: Minor | B15: Clarity of speech | C15: =COUNTIFS('QC Dump (clean)'!$L:$L,$B15,'QC Dump (clean)'!$M:$M,$A15,'QC Dump (clean)'!$R:$R,C$1) -> 0 | D15: =COUNTIFS('QC Dump (clean)'!$L:$L,$B15,'QC Dump (clean)'!$M:$M,$A15,'QC Dump (clean)'!$R:$R,D$1) -> 1 | E15: =SUM(C15:D15)
A16: Minor | B16: Distorted sound | C16: =COUNTIFS('QC Dump (clean)'!$L:$L,$B16,'QC Dump (clean)'!$M:$M,$A16,'QC Dump (clean)'!$R:$R,C$1) -> 0 | D16: =COUNTIFS('QC Dump (clean)'!$L:$L,$B16,'QC Dump (clean)'!$M:$M,$A16,'QC Dump (clean)'!$R:$R,D$1) -> 26 | E16: =SUM(C16:D16)
A17: Minor | B17: Fumble / Mumble | C17: =COUNTIFS('QC Dump (clean)'!$L:$L,$B17,'QC Dump (clean)'!$M:$M,$A17,'QC Dump (clean)'!$R:$R,C$1) -> 1 | D17: =COUNTIFS('QC Dump (clean)'!$L:$L,$B17,'QC Dump (clean)'!$M:$M,$A17,'QC Dump (clean)'!$R:$R,D$1) -> 1 | E17: =SUM(C17:D17)
A18: Minor | B18: Modulation | C18: =COUNTIFS('QC Dump (clean)'!$L:$L,$B18,'QC Dump (clean)'!$M:$M,$A18,'QC Dump (clean)'!$R:$R,C$1) -> 33 | D18: =COUNTIFS('QC Dump (clean)'!$L:$L,$B18,'QC Dump (clean)'!$M:$M,$A18,'QC Dump (clean)'!$R:$R,D$1) -> 52 | E18: =SUM(C18:D18)
A19: Minor | B19: Physical noise of VOA | C19: =COUNTIFS('QC Dump (clean)'!$L:$L,$B19,'QC Dump (clean)'!$M:$M,$A19,'QC Dump (clean)'!$R:$R,C$1) -> 1 | D19: =COUNTIFS('QC Dump (clean)'!$L:$L,$B19,'QC Dump (clean)'!$M:$M,$A19,'QC Dump (clean)'!$R:$R,D$1) -> 3 | E19: =SUM(C19:D19)
A20: Minor | B20: Repetition | C20: =COUNTIFS('QC Dump (clean)'!$L:$L,$B20,'QC Dump (clean)'!$M:$M,$A20,'QC Dump (clean)'!$R:$R,C$1) -> 1 | D20: =COUNTIFS('QC Dump (clean)'!$L:$L,$B20,'QC Dump (clean)'!$M:$M,$A20,'QC Dump (clean)'!$R:$R,D$1) -> 3 | E20: =SUM(C20:D20)
A21: Minor | B21: Sibilance | C21: =COUNTIFS('QC Dump (clean)'!$L:$L,$B21,'QC Dump (clean)'!$M:$M,$A21,'QC Dump (clean)'!$R:$R,C$1) -> 0 | D21: =COUNTIFS('QC Dump (clean)'!$L:$L,$B21,'QC Dump (clean)'!$M:$M,$A21,'QC Dump (clean)'!$R:$R,D$1) -> 1 | E21: =SUM(C21:D21)
A22: Minor | B22: Tone change | C22: =COUNTIFS('QC Dump (clean)'!$L:$L,$B22,'QC Dump (clean)'!$M:$M,$A22,'QC Dump (clean)'!$R:$R,C$1) -> 3 | D22: =COUNTIFS('QC Dump (clean)'!$L:$L,$B22,'QC Dump (clean)'!$M:$M,$A22,'QC Dump (clean)'!$R:$R,D$1) -> 15 | E22: =SUM(C22:D22)
... A24: Minor | B24: Voice processing & editing | C24: =COUNTIFS('QC Dump (clean)'!$L:$L,$B24,'QC Dump (clean)'!$M:$M,$A24,'QC Dump (clean)'!$R:$R,C$1) -> 1 | D24: =COUNTIFS('QC Dump (clean)'!$L:$L,$B24,'QC Dump (clean)'!$M:$M,$A24,'QC Dump (clean)'!$R:$R,D$1) -> 29 | E24: =SUM(C24:D24)
A25: Unclassified | B25: All Unclassified | C25: =COUNTIFS('QC Dump (clean)'!$M:$M,$A25,'QC Dump (clean)'!$R:$R,C$1) -> 0 | D25: =COUNTIFS('QC Dump (clean)'!$M:$M,$A25,'QC Dump (clean)'!$R:$R,D$1) -> 2 | E25: =SUM(C25:D25)
A26: Unclassified | B26: BGM/SFX | C26: =COUNTIFS('QC Dump (clean)'!$L:$L,$B26,'QC Dump (clean)'!$M:$M,$A26,'QC Dump (clean)'!$R:$R,C$1) -> 0 | D26: =COUNTIFS('QC Dump (clean)'!$L:$L,$B26,'QC Dump (clean)'!$M:$M,$A26,'QC Dump (clean)'!$R:$R,D$1) -> 2 | E26: =SUM(C26:D26)
B27: Total errors | C27: =COUNTIFS('QC Dump (clean)'!$M:$M,"<>Not an error",'QC Dump (clean)'!$R:$R,C$1) -> 1935 | D27: =COUNTIFS('QC Dump (clean)'!$M:$M,"<>Not an error",'QC Dump (clean)'!$R:$R,D$1) -> 3903 | E27: =SUM(C27:D27)
B28: Pending | C28: =COUNTIFS('QC Dump (clean)'!$H:$H,"Pending",'QC Dump (clean)'!$M:$M,"<>Not an error",'QC Dump (clean)'!$R:$R,C$1) -> 348 | D28: =COUNTIFS('QC Dump (clean)'!$H:$H,"Pending",'QC Dump (clean)'!$M:$M,"<>Not an error",'QC Dump (clean)'!$R:$R,D$1) -> 1361 | E28: =SUM(C28:D28)

Sheet QC Dump (clean)
A1: Show ID | B1: Show name | C1: DE title | D1: Chapter ID | E1: Episode title | F1: Ep No | G1: Time | H1: Status | I1: Remarks | J1: Category | K1: Issue type (QC tool) | L1: Issue type | M1: Severity | N1: Reviewer | O1: Audio status | P1: Stage | Q1: Logged | R1: Month | S1: Unique ep (error) | T1: Unique ep (Major) | U1: Unique ep (Minor)
A2: 341e3264241ee949f8140798461d1a30ee308d63 | B2: A Sacrifice That Lived | C2: Die Opferbraut Des Bestienkönigs | D2: 706035395dd365ecb054558169485e9e371afbfc | E2: Episode 3: Kians Sturm | F2: 3 | G2: 0:19-0:28 | H2: Resolved | I2: formal -> informal - „Ihr tut ja so, als hättet Ihr sie noch nie gesehen. Ihr seid die Erste Prinzessin von Heilachaten. Ihr müsst das doch jeden Frühling sehen.“ | J2: AI | K2: Script error | L2: Script error | M2: =IFERROR(IF(VLOOKUP(L2,'Quantification'!$A:$B,2,FALSE)&""="","Unclassified",VLOOKUP(L2,'Quantification'!$A:$B,2,FALSE)),"Unclassified") -> Major | N2: frl-denis.sobol@pocketfm.com | O2: Issues found in raw | P2: =IF(OR(O2="Issues found in master",O2="Final master"),"Master",IF(OR(O2="Ready for Master",O2="Issues found in raw",O2="Raw under QC",O2="Issues resolved in raw"),"Raw","-")) -> Raw | Q2: 46280.615 | R2: 2026-09 (Sept) | S2: =IF(M2="Not an error",0,IF(COUNTIFS($A$2:$A2,$A2,$D$2:$D2,$D2,$M$2:$M2,"<>Not an error")=1,1,0)) -> 1 | T2: =IF(M2<>"Major",0,IF(COUNTIFS($A$2:$A2,$A2,$D$2:$D2,$D2,$M$2:$M2,"Major")=1,1,0)) -> 1 | U2: =IF(M2<>"Minor",0,IF(COUNTIFS($A$2:$A2,$A2,$D$2:$D2,$D2,$M$2:$M2,"Minor")=1,1,0)) -> 0
A3: 341e3264241ee949f8140798461d1a30ee308d63 | B3: A Sacrifice That Lived | C3: Die Opferbraut Des Bestienkönigs | D3: 706035395dd365ecb054558169485e9e371afbfc | E3: Episode 3: Kians Sturm | F3: 3 | G3: 1:10-1:13 | H3: Resolved | I3: formal -> informal - „Hat Eure Mutter Euch meinen Namen nicht gesagt?“ | J3: AI | K3: Script error | L3: Script error | M3: =IFERROR(IF(VLOOKUP(L3,'Quantification'!$A:$B,2,FALSE)&""="","Unclassified",VLOOKUP(L3,'Quantification'!$A:$B,2,FALSE)),"Unclassified") -> Major | N3: frl-denis.sobol@pocketfm.com | O3: Issues found in raw | P3: =IF(OR(O3="Issues found in master",O3="Final master"),"Master",IF(OR(O3="Ready for Master",O3="Issues found in raw",O3="Raw under QC",O3="Issues resolved in raw"),"Raw","-")) -> Raw | Q3: 46280.615 | R3: 2026-09 (Sept) | S3: =IF(M3="Not an error",0,IF(COUNTIFS($A$2:$A3,$A3,$D$2:$D3,$D3,$M$2:$M3,"<>Not an error")=1,1,0)) -> 0 | T3: =IF(M3<>"Major",0,IF(COUNTIFS($A$2:$A3,$A3,$D$2:$D3,$D3,$M$2:$M3,"Major")=1,1,0)) -> 0 | U3: =IF(M3<>"Minor",0,IF(COUNTIFS($A$2:$A3,$A3,$D$2:$D3,$D3,$M$2:$M3,"Minor")=1,1,0)) -> 0
A4: 341e3264241ee949f8140798461d1a30ee308d63 | B4: A Sacrifice That Lived | C4: Die Opferbraut Des Bestienkönigs | D4: 706035395dd365ecb054558169485e9e371afbfc | E4: Episode 3: Kians Sturm | F4: 3 | G4: 1:38-1:56 | H4: Resolved | I4: formal -> informal - „Ihr seid unklug“, sagte er, und obwohl sie seine Augen nicht sehen konnte, spürte sie, wie sein Blick sie förmlich durchbohrte. „Ich habe mir die Zeit genommen, Euren Namen zu lernen, Prinzessin Liona von Heilachaten. Ihr jedoch hegt keinerlei Verlangen, meinen zu kennen.“ | J4: AI | K4: Script error | L4: Script error | M4: =IFERROR(IF(VLOOKUP(L4,'Quantification'!$A:$B,2,FALSE)&""="","Unclassified",VLOOKUP(L4,'Quantification'!$A:$B,2,FALSE)),"Unclassified") -> Major | N4: frl-denis.sobol@pocketfm.com | O4: Issues found in raw | P4: =IF(OR(O4="Issues found in master",O4="Final master"),"Master",IF(OR(O4="Ready for Master",O4="Issues found in raw",O4="Raw under QC",O4="Issues resolved in raw"),"Raw","-")) -> Raw | Q4: 46280.615 | R4: 2026-09 (Sept) | S4: =IF(M4="Not an error",0,IF(COUNTIFS($A$2:$A4,$A4,$D$2:$D4,$D4,$M$2:$M4,"<>Not an error")=1,1,0)) -> 0 | T4: =IF(M4<>"Major",0,IF(COUNTIFS($A$2:$A4,$A4,$D$2:$D4,$D4,$M$2:$M4,"Major")=1,1,0)) -> 0 | U4: =IF(M4<>"Minor",0,IF(COUNTIFS($A$2:$A4,$A4,$D$2:$D4,$D4,$M$2:$M4,"Minor")=1,1,0)) -> 0
A5: 341e3264241ee949f8140798461d1a30ee308d63 | B5: A Sacrifice That Lived | C5: Die Opferbraut Des Bestienkönigs | D5: 706035395dd365ecb054558169485e9e371afbfc | E5: Episode 3: Kians Sturm | F5: 3 | G5: 2:13-2:19 | H5: Resolved | I5: formal -> informal - „Kian“, sagte die Bestie mit leiser Stimme. „Unter vier Augen könnt Ihr mich Kian nennen.“ | J5: AI | K5: Script error | L5: Script error | M5: =IFERROR(IF(VLOOKUP(L5,'Quantification'!$A:$B,2,FALSE)&""="","Unclassified",VLOOKUP(L5,'Quantification'!$A:$B,2,FALSE)),"Unclassified") -> Major | N5: frl-denis.sobol@pocketfm.com | O5: Issues found in raw | P5: =IF(OR(O5="Issues found in master",O5="Final master"),"Master",IF(OR(O5="Ready for Master",O5="Issues found in raw",O5="Raw under QC",O5="Issues resolved in raw"),"Raw","-")) -> Raw | Q5: 46280.615 | R5: 2026-09 (Sept) | S5: =IF(M5="Not an error",0,IF(COUNTIFS($A$2:$A5,$A5,$D$2:$D5,$D5,$M$2:$M5,"<>Not an error")=1,1,0)) -> 0 | T5: =IF(M5<>"Major",0,IF(COUNTIFS($A$2:$A5,$A5,$D$2:$D5,$D5,$M$2:$M5,"Major")=1,1,0)) -> 0 | U5: =IF(M5<>"Minor",0,IF(COUNTIFS($A$2:$A5,$A5,$D$2:$D5,$D5,$M$2:$M5,"Minor")=1,1,0)) -> 0
A6: 341e3264241ee949f8140798461d1a30ee308d63 | B6: A Sacrifice That Lived | C6: Die Opferbraut Des Bestienkönigs | D6: 706035395dd365ecb054558169485e9e371afbfc | E6: Episode 3: Kians Sturm | F6: 3 | G6: 2:38-2:42 | H6: Resolved | I6: formal -> informal - „Nur Kian. Ich bin nicht Euer Meister und Ihr seid nicht meine Dienerin“, sagte er schroff. | J6: AI | K6: Script error | L6: Script error | M6: =IFERROR(IF(VLOOKUP(L6,'Quantification'!$A:$B,2,FALSE)&""="","Unclassified",VLOOKUP(L6,'Quantification'!$A:$B,2,FALSE)),"Unclassified") -> Major | N6: frl-denis.sobol@pocketfm.com | O6: Issues found in raw | P6: =IF(OR(O6="Issues found in master",O6="Final master"),"Master",IF(OR(O6="Ready for Master",O6="Issues found in raw",O6="Raw under QC",O6="Issues resolved in raw"),"Raw","-")) -> Raw | Q6: 46280.615 | R6: 2026-09 (Sept) | S6: =IF(M6="Not an error",0,IF(COUNTIFS($A$2:$A6,$A6,$D$2:$D6,$D6,$M$2:$M6,"<>Not an error")=1,1,0)) -> 0 | T6: =IF(M6<>"Major",0,IF(COUNTIFS($A$2:$A6,$A6,$D$2:$D6,$D6,$M$2:$M6,"Major")=1,1,0)) -> 0 | U6: =IF(M6<>"Minor",0,IF(COUNTIFS($A$2:$A6,$A6,$D$2:$D6,$D6,$M$2:$M6,"Minor")=1,1,0)) -> 0
